Workbook

Sheet PAYROLL
A1: 6 | B1: =112000/56 -> 2000 | C1: 45960 | F1: =$G$2-$F$2+1 -> 30 | O1: 0 | Q1: ANNUAL RENT IS ON CELL AF4 | Y1: Delivery Penalty | Z1: =21000/700 -> 30
F2: 45901 | G2: 45930 | O2: 0 | Y2: LATE COMING x2
A3: S/N | B3: NAMES | C3: DESIGNATION | D3: EMP ID | E3: START DATE | F3: MONTH START DATE | G3: MONTH END DATE | H3: WORKED DAYS | I3: BASIC | J3: HOUSING | K3: TRANSPORT | L3: UTILITY | M3: MEAL | N3: TOTAL INCOME | O3: BONUS | P3: perf REWARD | Q3: GROSS PAY | R3: PENSION | S3: PAYE | T3: HMO | U3: NHF | V3: OTHER DEDUCTION | W3: LOAN REPAYMENT | X3: PENALTY | Y3: REASON | Z3: TOTAL DEDUCTIONS | AA3: NET SALARY | AB3: BANK | AC3: ACC NUMBER | AD3: EMAIL ADDRESS | AE3: RSA PIN | AF3: TAX ID | AG3: ANNUAL RENT | AH3: COUNT OF ACC NUM | AI3: COUNT OF RSA PIN
A4: 1 | B4: SALIU AMINU | C4: MANAGING DIRECTOR | D4: OTL/0009 | E4: 45628 | F4: =$F$2 -> 45901 | G4: =$G$2 -> 45930 | H4: =G4-F4+1&" DAYS" -> 30 DAYS | I4: =30%*N4 -> 81000 | J4: =30%*N4 -> 81000 | K4: =20%*N4 -> 54000 | L4: =10%*N4 -> 27000 | M4: =10%*N4 -> 27000 | N4: =(270000/$F$1*(G4-F4+1)) -> 270000 | O4: 25000 | P4: 0 | Q4: =SUM(N4:P4) -> 295000 | R4: =8%*(SUM(I4:K4)) -> 17280 | S4: ₦26,408.00 | T4: 0 | U4: 0 | V4: 0 | W4: 0 | X4: 0 | Y4: N/A | Z4: =SUM(R4:X4) -> 17280 | AA4: =Q4-Z4 -> 277720 | AB4: ACCESS BANK | AC4: 3849201756 | AD4: XXY@GMAIL.COM | AE4: PENXXXXXXXXXXXX | AF4: ABFT3@ | AG4: 600000 | AH4: =LEN(AC4) -> 10 | AI4: =LEN(AE4) -> 15
A5: =IF(B5="","",A4+1) -> 2 | B5: OLUDAYO BANKE | C5: EXECUTIVE ASSISTANT | D5: OTL/0036 | E5: 45845 | F5: =$F$2 -> 45901 | G5: =$G$2 -> 45930 | H5: =G5-F5+1&" DAYS" -> 30 DAYS | I5: =30%*N5 -> 24000 | J5: =30%*N5 -> 24000 | K5: =20%*N5 -> 16000 | L5: =10%*N5 -> 8000 | M5: =10%*N5 -> 8000 | N5: =(80000/$F$1*(G5-F5+1)) -> 80000 | O5: =$O$1 -> 0 | P5: 0 | Q5: =SUM(N5:P5) -> 80000 | R5: =8%*(SUM(I5:K5)) -> 5120 | S5: ₦482.00 | T5: 0 | U5: 0 | V5: 0 | W5: 0 | X5: 0 | Y5: N/A | Z5: =SUM(R5:X5) -> 5120 | AA5: =Q5-Z5 -> 74880 | AB5: UNITED BANK FOR AFRICA | AC5: 7293846150 | AD5: XXY@GMAIL.COM | AE5: PENXXXXXXXXXXXX | AF5: ZXLP9# | AG5: 300000 | AH5: =LEN(AC5) -> 10 | AI5: =LEN(AE5) -> 15
A6: =IF(B6="","",A5+1) -> 3 | B6: CHRISTOPHER HANNAH | C6: OFFICE ADMINISTRATOR | D6: OTL/0058 | E6: 45896 | F6: 45915 | G6: =$G$2 -> 45930 | H6: =G6-F6+1&" DAYS" -> 16 DAYS | I6: =30%*N6 -> 52000 | J6: =30%*N6 -> 52000 | K6: =20%*N6 -> 34666.667 | L6: =10%*N6 -> 17333.333 | M6: =10%*N6 -> 17333.333 | N6: =(325000/$F$1*(G6-F6+1)) -> 173333.33 | O6: =$O$1 -> 0 | P6: 0 | Q6: =SUM(N6:P6) -> 173333.33 | R6: =8%*(SUM(I6:K6)) -> 11093.333 | S6: ₦13,586.00 | T6: 0 | U6: 0 | V6: 0 | W6: 0 | X6: 0 | Y6: N/A | Z6: =SUM(R6:X6) -> 11093.333 | AA6: =Q6-Z6 -> 162240 | AB6: UBA | AC6: 1059384726 | AD6: XXY@GMAIL.COM | AE6: PENXXXXXXXXXXXX | AF6: MNQR2& | AG6: 300000 | AH6: =LEN(AC6) -> 10 | AI6: =LEN(AE6) -> 15
A7: =IF(B7="","",A6+1) -> 4 | B7: OJO ABIGAIL | C7: RECEPTIONIST | D7: OTL/0014 | E7: 45798 | F7: =$F$2 -> 45901 | G7: =$G$2 -> 45930 | H7: =G7-F7+1&" DAYS" -> 30 DAYS | I7: =30%*N7 -> 54000 | J7: =30%*N7 -> 54000 | K7: =20%*N7 -> 36000 | L7: =10%*N7 -> 18000 | M7: =10%*N7 -> 18000 | N7: =(180000/$F$1*(G7-F7+1)) -> 180000 | O7: =$O$1 -> 0 | P7: 0 | Q7: =SUM(N7:P7) -> 180000 | R7: =8%*(SUM(I7:K7)) -> 11520 | S7: ₦14,522.00 | T7: 0 | U7: 0 | V7: 0 | W7: 0 | X7: 0 | Y7: N/A | Z7: =SUM(R7:X7) -> 11520 | AA7: =Q7-Z7 -> 168480 | AB7: UNITED BANK FOR AFRICA | AC7: 4928375610 | AD7: XXY@GMAIL.COM | AE7: PENXXXXXXXXXXXX | AF7: VWCD7^ | AG7: 300000 | AH7: =LEN(AC7) -> 10 | AI7: =LEN(AE7) -> 15
A8: =IF(B8="","",A7+1) -> 5 | B8: Abdulkadir Rahis | C8: COMPANY SECRETARY | D8: OTL/0032 | E8: 45761 | F8: =$F$2 -> 45901 | G8: =$G$2 -> 45930 | H8: =G8-F8+1&" DAYS" -> 30 DAYS | I8: =30%*N8 -> 45000 | J8: =30%*N8 -> 45000 | K8: =20%*N8 -> 30000 | L8: =10%*N8 -> 15000 | M8: =10%*N8 -> 15000 | N8: =(150000/$F$1*(G8-F8+1)) -> 150000 | O8: =$O$1 -> 0 | P8: 0 | Q8: =SUM(N8:P8) -> 150000 | R8: =8%*(SUM(I8:K8)) -> 9600 | S8: ₦10,310.00 | T8: 0 | U8: 0 | V8: 0 | W8: 0 | X8: 0 | Y8: N/A | Z8: =SUM(R8:X8) -> 9600 | AA8: =Q8-Z8 -> 140400 | AB8: UNITED BANK FOR AFRICA | AC8: 8372619405 | AD8: XXY@GMAIL.COM | AE8: PENXXXXXXXXXXXX | AF8: HJKL1@ | AG8: 300000 | AH8: =LEN(AC8) -> 10 | AI8: =LEN(AE8) -> 15
A9: =IF(B9="","",A8+1) -> 6 | B9: Abdullahi Dabai | C9: HR MANAGER | D9: OTL/0005 | E9: 45489 | F9: =$F$2 -> 45901 | G9: =$G$2 -> 45930 | H9: =G9-F9+1&" DAYS" -> 30 DAYS | I9: =30%*N9 -> 81000 | J9: =30%*N9 -> 81000 | K9: =20%*N9 -> 54000 | L9: =10%*N9 -> 27000 | M9: =10%*N9 -> 27000 | N9: =(270000/$F$1*(G9-F9+1)) -> 270000 | O9: =$O$1 -> 0 | P9: 0 | Q9: =SUM(N9:P9) -> 270000 | R9: 0 | S9: ₦29,600.00 | T9: 0 | U9: 0 | V9: 0 | W9: 0 | X9: 0 | Y9: N/A | Z9: =SUM(R9:X9) -> 0 | AA9: =Q9-Z9 -> 270000 | AB9: ACCESS BANK | AC9: 9182736450 | AD9: XXY@GMAIL.COM | AE9: PENXXXXXXXXXXXX | AF9: QRST8# | AG9: 500000 | AH9: =LEN(AC9) -> 10 | AI9: =LEN(AE9) -> 15
A10: =IF(B10="","",A9+1) -> 7 | B10: Abdullahi Idris Garba | C10: HR OFFICER | D10: OTL/0013 | E10: 45495 | F10: =$F$2 -> 45901 | G10: =$G$2 -> 45930 | H10: =G10-F10+1&" DAYS" -> 30 DAYS | I10: =30%*N10 -> 36000 | J10: =30%*N10 -> 36000 | K10: =20%*N10 -> 24000 | L10: =10%*N10 -> 12000 | M10: =10%*N10 -> 12000 | N10: =(120000/$F$1*(G10-F10+1)) -> 120000 | O10: 0 | P10: 0 | Q10: =SUM(N10:P10) -> 120000 | R10: 0 | S10: ₦7,250.00 | T10: 0 | U10: 0 | V10: 0 | W10: 0 | X10: 0 | Y10: N/A | Z10: =SUM(R10:X10) -> 0 | AA10: =Q10-Z10 -> 120000 | AB10: ZENITH BANK | AC10: 2039485761 | AD10: XXY@GMAIL.COM | AE10: PENXXXXXXXXXXXX | AF10: EFGH4& | AG10: 300000 | AH10: =LEN(AC10) -> 10 | AI10: =LEN(AE10) -> 15
A11: =IF(B11="","",A10+1) -> 8 | B11: Abdullahi Mamudu | C11: TALENT ACQUISITION SPECIALIST | D11: OTL/0016 | E11: 44816 | F11: =$F$2 -> 45901 | G11: =$G$2 -> 45930 | H11: =G11-F11+1&" DAYS" -> 30 DAYS | I11: =30%*N11 -> 24000 | J11: =30%*N11 -> 24000 | K11: =20%*N11 -> 16000 | L11: =10%*N11 -> 8000 | M11: =10%*N11 -> 8000 | N11: =(80000/$F$1*(G11-F11+1)) -> 80000 | O11: 0 | P11: 0 | Q11: =SUM(N11:P11) -> 80000 | R11: 0 | S11: ₦1,250.00 | T11: 0 | U11: 0 | V11: 0 | W11: 0 | X11: 0 | Y11: N/A | Z11: =SUM(R11:X11) -> 0 | AA11: =Q11-Z11 -> 80000 | AB11: UNITED BANK FOR AFRICA | AC11: 6574839201 | AD11: XXY@GMAIL.COM | AE11: PENXXXXXXXXXXXX | AF11: YUIO6^ | AG11: 300000 | AH11: =LEN(AC11) -> 10 | AI11: =LEN(AE11) -> 15
A12: =IF(B12="","",A11+1) -> 9 | B12: Abdullahi Sani | C12: TRAINING & DEVELOPMENT OFFICER | D12: OTL/0017 | E12: 45544 | F12: =$F$2 -> 45901 | G12: =$G$2 -> 45930 | H12: =G12-F12+1&" DAYS" -> 30 DAYS | I12: =30%*N12 -> 24000 | J12: =30%*N12 -> 24000 | K12: =20%*N12 -> 16000 | L12: =10%*N12 -> 8000 | M12: =10%*N12 -> 8000 | N12: =(80000/$F$1*(G12-F12+1)) -> 80000 | O12: 0 | P12: 0 | Q12: =SUM(N12:P12) -> 80000 | R12: 0 | S12: ₦1,250.00 | T12: 0 | U12: 0 | V12: 0 | W12: 0 | X12: 0 | Y12: N/A | Z12: =SUM(R12:X12) -> 0 | AA12: =Q12-Z12 -> 80000 | AB12: ACCESS BANK | AC12: 3847561920 | AD12: XXY@GMAIL.COM | AE12: PENXXXXXXXXXXXX | AF12: BNML5@ | AG12: 300000 | AH12: =LEN(AC12) -> 10 | AI12: =LEN(AE12) -> 15
A13: =IF(B13="","",A12+1) -> 10 | B13: Abdulmalik Zubairu | C13: PAYROLL OFFICER | D13: OTL/0007 | E13: 45628 | F13: =$F$2 -> 45901 | G13: =$G$2 -> 45930 | H13: =G13-F13+1&" DAYS" -> 30 DAYS | I13: =30%*N13 -> 24000 | J13: =30%*N13 -> 24000 | K13: =20%*N13 -> 16000 | L13: =10%*N13 -> 8000 | M13: =10%*N13 -> 8000 | N13: =(80000/$F$1*(G13-F13+1)) -> 80000 | O13: 0 | P13: 0 | Q13: =SUM(N13:P13) -> 80000 | R13: 0 | S13: ₦1,250.00 | T13: 0 | U13: 0 | V13: 0 | W13: 0 | X13: 0 | Y13: N/A | Z13: =SUM(R13:X13) -> 0 | AA13: =Q13-Z13 -> 80000 | AB13: UNITED BANK FOR AFRICA | AC13: 7461928305 | AD13: XXY@GMAIL.COM | AE13: PENXXXXXXXXXXXX | AF13: TZXC0# | AG13: 300000 | AH13: =LEN(AC13) -> 10 | AI13: =LEN(AE13) -> 15
A14: =IF(B14="","",A13+1) -> 11 | B14: Abdulmumin Ari Mohammed | C14: CHIEF FINANCIAL OFFICER | D14: OTL/0004 | E14: 43502 | F14: =$F$2 -> 45901 | G14: =$G$2 -> 45930 | H14: =G14-F14+1&" DAYS" -> 30 DAYS | I14: =30%*N14 -> 36000 | J14: =30%*N14 -> 36000 | K14: =20%*N14 -> 24000 | L14: =10%*N14 -> 12000 | M14: =10%*N14 -> 12000 | N14: =(120000/$F$1*(G14-F14+1)) -> 120000 | O14: 0 | P14: 0 | Q14: =SUM(N14:P14) -> 120000 | R14: 0 | S14: ₦7,250.00 | T14: 0 | U14: 0 | V14: 0 | W14: 50000 | X14: 0 | Y14: N/A | Z14: =SUM(R14:X14) -> 50000 | AA14: =Q14-Z14 -> 70000 | AB14: UNITED BANK FOR AFRICA | AC14: 5829301746 | AD14: XXY@GMAIL.COM | AE14: PENXXXXXXXXXXXX | AF14: DEFG2& | AG14: 300000 | AH14: =LEN(AC14) -> 10 | AI14: =LEN(AE14) -> 15
A15: =IF(B15="","",A14+1) -> 12 | B15: Abdulraheem Abdulmaleek | C15: ACCOUNTANT | D15: OTL/0003 | E15: 45530 | F15: =$F$2 -> 45901 | G15: =$G$2 -> 45930 | H15: =G15-F15+1&" DAYS" -> 30 DAYS | I15: =30%*N15 -> 24000 | J15: =30%*N15 -> 24000 | K15: =20%*N15 -> 16000 | L15: =10%*N15 -> 8000 | M15: =10%*N15 -> 8000 | N15: =(80000/$F$1*(G15-F15+1)) -> 80000 | O15: 0 | P15: 0 | Q15: =SUM(N15:P15) -> 80000 | R15: 0 | S15: 0 | T15: 0 | U15: 0 | V15: 0 | W15: 0 | X15: 0 | Y15: N/A | Z15: =SUM(R15:X15) -> 0 | AA15: =Q15-Z15 -> 80000 | AB15: UNITED BANK FOR AFRICA | AC15: 1092837465 | AD15: XXY@GMAIL.COM | AE15: PENXXXXXXXXXXXX | AF15: WQER9^ | AG15: 300000 | AH15: =LEN(AC15) -> 10 | AI15: =LEN(AE15) -> 15
A16: =IF(B16="","",A15+1) -> 13 | B16: Abdulraheem Olatunji Olawuyi | C16: ACCOUNTANT | D16: OTL/0027 | E16: 45728 | F16: =$F$2 -> 45901 | G16: =$G$2 -> 45930 | H16: =G16-F16&" DAYS" -> 29 DAYS | I16: =30%*N16 -> 24000 | J16: =30%*N16 -> 24000 | K16: =20%*N16 -> 16000 | L16: =10%*N16 -> 8000 | M16: =10%*N16 -> 8000 | N16: =(80000/$F$1*(G16-F16+1)) -> 80000 | O16: 0 | P16: 0 | Q16: =SUM(N16:P16) -> 80000 | R16: 0 | S16: 0 | T16: 0 | U16: 0 | V16: 0 | W16: 0 | X16: 0 | Y16: N/A | Z16: =SUM(R16:X16) -> 0 | AA16: =Q16-Z16 -> 80000 | AB16: UNITED BANK FOR AFRICA | AC16: 8473629105 | AD16: XXY@GMAIL.COM | AE16: PENXXXXXXXXXXXX | AF16: JKLM3@ | AG16: 300000 | AH16: =LEN(AC16) -> 10 | AI16: =LEN(AE16) -> 15
A17: =IF(B17="","",A16+1) -> 14 | B17: Abiodun James Faleke | C17: ACCOUNTS PAYABLE OFFICER | D17: OTL/0028 | E17: 45736 | F17: =$F$2 -> 45901 | G17: =$G$2 -> 45930 | H17: =G17-F17+1&" DAYS" -> 30 DAYS | I17: =30%*N17 -> 24000 | J17: =30%*N17 -> 24000 | K17: =20%*N17 -> 16000 | L17: =10%*N17 -> 8000 | M17: =10%*N17 -> 8000 | N17: =(80000/$F$1*(G17-F17+1)) -> 80000 | O17: 0 | P17: 0 | Q17: =SUM(N17:P17) -> 80000 | R17: 0 | S17: 0 | T17: 0 | U17: 0 | V17: 0 | W17: 0 | X17: 0 | Y17: N/A | Z17: =SUM(R17:X17) -> 0 | AA17: =Q17-Z17 -> 80000 | AB17: ZENITH BANK | AC17: 2948573610 | AD17: XXY@GMAIL.COM | AE17: PENXXXXXXXXXXXX | AF17: ASDF7# | AG17: 300000 | AH17: =LEN(AC17) -> 10 | AI17: =LEN(AE17) -> 15
A18: =IF(B18="","",A17+1) -> 15 | B18: Abiola Peter Makinde | C18: ACCOUNTS RECEIVABLE OFFICER | D18: OTL/0033 | E18: 45810 | F18: =$F$2 -> 45901 | G18: =$G$2 -> 45930 | H18: =G18-F18+1&" DAYS" -> 30 DAYS | I18: =30%*N18 -> 24000 | J18: =30%*N18 -> 24000 | K18: =20%*N18 -> 16000 | L18: =10%*N18 -> 8000 | M18: =10%*N18 -> 8000 | N18: =(80000/$F$1*(G18-F18+1)) -> 80000 | O18: 0 | P18: 0 | Q18: =SUM(N18:P18) -> 80000 | R18: 0 | S18: 0 | T18: 0 | U18: 0 | V18: 0 | W18: 0 | X18: 0 | Y18: N/A | Z18: =SUM(R18:X18) -> 0 | AA18: =Q18-Z18 -> 80000 | AB18: FIRST BANK OF NIGERIA | AC18: 7362910485 | AD18: XXY@GMAIL.COM | AE18: PENXXXXXXXXXXXX | AF18: GHIJ1& | AG18: 300000 | AH18: =LEN(AC18) -> 10 | AI18: =LEN(AE18) -> 15
A19: =IF(B19="","",A18+1) -> 16 | B19: Abonsizibe Oforji Obuku | C19: INTERNAL AUDITOR | D19: OTL/0011 | E19: 45628 | F19: =$F$2 -> 45901 | G19: =$G$2 -> 45930 | H19: =G19-F19+1&" DAYS" -> 30 DAYS | I19: =30%*N19 -> 24000 | J19: =30%*N19 -> 24000 | K19: =20%*N19 -> 16000 | L19: =10%*N19 -> 8000 | M19: =10%*N19 -> 8000 | N19: =(80000/$F$1*(G19-F19+1)) -> 80000 | O19: 0 | P19: 0 | Q19: =SUM(N19:P19) -> 80000 | R19: 0 | S19: 0 | T19: 0 | U19: 0 | V19: 0 | W19: 0 | X19: 0 | Y19: N/A | Z19: =SUM(R19:X19) -> 0 | AA19: =Q19-Z19 -> 80000 | AB19: FIRST BANK OF NIGERIA | AC19: 9183746250 | AD19: XXY@GMAIL.COM | AE19: PENXXXXXXXXXXXX | AF19: ZXCV6^ | AG19: 300000 | AH19: =LEN(AC19) -> 10 | AI19: =LEN(AE19) -> 15
A20: =IF(B20="","",A19+1) -> 17 | B20: Abubakar Ahmad Mohammed | C20: FINANCE ANALYST | D20: OTL/0012 | E20: 45567 | F20: =$F$2 -> 45901 | G20: =$G$2 -> 45930 | H20: =G20-F20+1&" DAYS" -> 30 DAYS | I20: =30%*N20 -> 24000 | J20: =30%*N20 -> 24000 | K20: =20%*N20 -> 16000 | L20: =10%*N20 -> 8000 | M20: =10%*N20 -> 8000 | N20: =(80000/$F$1*(G20-F20+1)) -> 80000 | O20: 0 | P20: 0 | Q20: =SUM(N20:P20) -> 80000 | R20: 0 | S20: 0 | T20: 0 | U20: 0 | V20: 0 | W20: 0 | X20: 0 | Y20: N/A | Z20: =SUM(R20:X20) -> 0 | AA20: =Q20-Z20 -> 80000 | AB20: FIRST BANK OF NIGERIA | AC20: 2039485716 | AD20: XXY@GMAIL.COM | AE20: PENXXXXXXXXXXXX | AF20: MNOP4@ | AG20: 300000 | AH20: =LEN(AC20) -> 10 | AI20: =LEN(AE20) -> 15
A21: =IF(B21="","",A20+1) -> 18 | B21: Abubakar Hassan Fulata | C21: OPERATIONS MANAGER | D21: OTL/0019 | E21: 45728 | F21: =$F$2 -> 45901 | G21: =$G$2 -> 45930 | H21: =G21-F21+1&" DAYS" -> 30 DAYS | I21: =30%*N21 -> 24000 | J21: =30%*N21 -> 24000 | K21: =20%*N21 -> 16000 | L21: =10%*N21 -> 8000 | M21: =10%*N21 -> 8000 | N21: =(80000/$F$1*(G21-F21+1)) -> 80000 | O21: 0 | P21: 0 | Q21: =SUM(N21:P21) -> 80000 | R21: 0 | S21: 0 | T21: 0 | U21: 0 | V21: 0 | W21: 0 | X21: 0 | Y21: N/A | Z21: =SUM(R21:X21) -> 0 | AA21: =Q21-Z21 -> 80000 | AB21: FIDELITY BANK | AC21: 6574839021 | AD21: XXY@GMAIL.COM | AE21: PENXXXXXXXXXXXX | AF21: QWER8# | AG21: 300000 | AH21: =LEN(AC21) -> 10 | AI21: =LEN(AE21) -> 15
A22: =IF(B22="","",A21+1) -> 19 | B22: Abubakar Hassan Nalaraba | C22: LOGISTICS COORDINATOR | D22: OTL/0034 | E22: 45810 | F22: =$F$2 -> 45901 | G22: =$G$2 -> 45930 | H22: =G22-F22+1&" DAYS" -> 30 DAYS | I22: =30%*N22 -> 24000 | J22: =30%*N22 -> 24000 | K22: =20%*N22 -> 16000 | L22: =10%*N22 -> 8000 | M22: =10%*N22 -> 8000 | N22: =(80000/$F$1*(G22-F22+1)) -> 80000 | O22: 0 | P22: 0 | Q22: =SUM(N22:P22) -> 80000 | R22: 0 | S22: 0 | T22: 0 | U22: 0 | V22: 0 | W22: 0 | X22: 0 | Y22: N/A | Z22: =SUM(R22:X22) -> 0 | AA22: =Q22-Z22 -> 80000 | AB22: MONIEPOINT MFB | AC22: 3847561290 | AD22: XXY@GMAIL.COM | AE22: PENXXXXXXXXXXXX | AF22: TYUI0& | AG22: 300000 | AH22: =LEN(AC22) -> 10 | AI22: =LEN(AE22) -> 15
A23: =IF(B23="","",A22+1) -> 20 | B23: Abubakar Kabir Abubakar | C23: PROCUREMENT OFFICER | D23: OTL/0025 | E23: 45728 | F23: =$F$2 -> 45901 | G23: =$G$2 -> 45930 | H23: =G23-F23+1&" DAYS" -> 30 DAYS | I23: =30%*N23 -> 24000 | J23: =30%*N23 -> 24000 | K23: =20%*N23 -> 16000 | L23: =10%*N23 -> 8000 | M23: =10%*N23 -> 8000 | N23: =(80000/$F$1*(G23-F23+1)) -> 80000 | O23: 0 | P23: 0 | Q23: =SUM(N23:P23) -> 80000 | R23: 0 | S23: 0 | T23: 0 | U23: 0 | V23: 0 | W23: 0 | X23: 0 | Y23: N/A | Z23: =SUM(R23:X23) -> 0 | AA23: =Q23-Z23 -> 80000 | AB23: FIDELITY BANK | AC23: 7461928350 | AD23: XXY@GMAIL.COM | AE23: PENXXXXXXXXXXXX | AF23: PASD5^ | AG23: 300000 | AH23: =LEN(AC23) -> 10 | AI23: =LEN(AE23) -> 15
A24: =IF(B24="","",A23+1) -> 21 | B24: Abubakar Sarki Dahiru | C24: INVENTORY OFFICER | D24: OTL/0026 | E24: 45728 | F24: =$F$2 -> 45901 | G24: =$G$2 -> 45930 | H24: =G24-F24+1&" DAYS" -> 30 DAYS | I24: =30%*N24 -> 24000 | J24: =30%*N24 -> 24000 | K24: =20%*N24 -> 16000 | L24: =10%*N24 -> 8000 | M24: =10%*N24 -> 8000 | N24: =(80000/$F$1*(G24-F24+1)) -> 80000 | O24: 0 | P24: 0 | Q24: =SUM(N24:P24) -> 80000 | R24: 0 | S24: 0 | T24: 0 | U24: 0 | V24: 0 | W24: 0 | X24: 0 | Y24: N/A | Z24: =SUM(R24:X24) -> 0 | AA24: =Q24-Z24 -> 80000 | AB24: OPAY | AC24: 5829301476 | AD24: XXY@GMAIL.COM | AE24: PENXXXXXXXXXXXX | AF24: LOPK3@ | AG24: 300000 | AH24: =LEN(AC24) -> 10 | AI24: =LEN(AE24) -> 15
A25: =IF(B25="","",A24+1) -> 22 | B25: Abubakar Yabo Umaru | C25: WAREHOUSE SUPERVISOR | D25: OTL/0015 | E25: 45530 | F25: =$F$2 -> 45901 | G25: =$G$2 -> 45930 | H25: =G25-F25+1&" DAYS" -> 30 DAYS | I25: =30%*N25 -> 24000 | J25: =30%*N25 -> 24000 | K25: =20%*N25 -> 16000 | L25: =10%*N25 -> 8000 | M25: =10%*N25 -> 8000 | N25: =(80000/$F$1*(G25-F25+1)) -> 80000 | O25: 0 | P25: 0 | Q25: =SUM(N25:P25) -> 80000 | R25: 0 | S25: 0 | T25: 0 | U25: 0 | V25: 0 | W25: 0 | X25: 0 | Y25: N/A | Z25: =SUM(R25:X25) -> 0 | AA25: =Q25-Z25 -> 80000 | AB25: PALMPAY | AC25: 1092837645 | AD25: XXY@GMAIL.COM | AE25: PENXXXXXXXXXXXX | AF25: VBNM9# | AG25: 300000 | AH25: =LEN(AC25) -> 10 | AI25: =LEN(AE25) -> 15
A26: =IF(B26="","",A25+1) -> 23 | B26: Adamu Hashimu | C26: DISPATCH RIDER | D26: OTL/0018 | E26: 45544 | F26: =$F$2 -> 45901 | G26: =$G$2 -> 45930 | H26: =G26-F26+1&" DAYS" -> 30 DAYS | I26: =30%*N26 -> 24000 | J26: =30%*N26 -> 24000 | K26: =20%*N26 -> 16000 | L26: =10%*N26 -> 8000 | M26: =10%*N26 -> 8000 | N26: =(80000/$F$1*(G26-F26+1)) -> 80000 | O26: 0 | P26: 0 | Q26: =SUM(N26:P26) -> 80000 | R26: 0 | S26: 0 | T26: 0 | U26: 0 | V26: 0 | W26: 0 | X26: 0 | Y26: N/A | Z26: =SUM(R26:X26) -> 0 | AA26: =Q26-Z26 -> 80000 | AB26: ACCESS BANK | AC26: 8473629015 | AD26: XXY@GMAIL.COM | AE26: PENXXXXXXXXXXXX | AF26: RTYU2& | AG26: 300000 | AH26: =LEN(AC26) -> 10 | AI26: =LEN(AE26) -> 15
A27: =IF(B27="","",A26+1) -> 24 | B27: Adamu Ibrahim Gamawa | C27: DISPATCH RIDER | D27: OTL/0031 | E27: 45758 | F27: =$F$2 -> 45901 | G27: =$G$2 -> 45930 | H27: =G27-F27+1&" DAYS" -> 30 DAYS | I27: =30%*N27 -> 24000 | J27: =30%*N27 -> 24000 | K27: =20%*N27 -> 16000 | L27: =10%*N27 -> 8000 | M27: =10%*N27 -> 8000 | N27: =(80000/$F$1*(G27-F27+1)) -> 80000 | O27: 0 | P27: 0 | Q27: =SUM(N27:P27) -> 80000 | R27: 0 | S27: 0 | T27: 0 | U27: 0 | V27: 0 | W27: 0 | X27: 0 | Y27: N/A | Z27: =SUM(R27:X27) -> 0 | AA27: =Q27-Z27 -> 80000 | AB27: OPAY | AC27: 2948573160 | AD27: XXY@GMAIL.COM | AE27: PENXXXXXXXXXXXX | AF27: EIWO7^ | AG27: 300000 | AH27: =LEN(AC27) -> 10 | AI27: =LEN(AE27) -> 15
A28: =IF(B28="","",A27+1) -> 25 | B28: Adamu Tanko | C28: IT MANAGER | D28: OTL/0022 | E28: 45551 | F28: =$F$2 -> 45901 | G28: =$G$2 -> 45930 | H28: =G28-F28+1&" DAYS" -> 30 DAYS | I28: =30%*N28 -> 24000 | J28: =30%*N28 -> 24000 | K28: =20%*N28 -> 16000 | L28: =10%*N28 -> 8000 | M28: =10%*N28 -> 8000 | N28: =(80000/$F$1*(G28-F28+1)) -> 80000 | O28: 0 | P28: 0 | Q28: =SUM(N28:P28) -> 80000 | R28: 0 | S28: 0 | T28: 0 | U28: 0 | V28: 0 | W28: 0 | X28: 0 | Y28: N/A | Z28: =SUM(R28:X28) -> 0 | AA28: =Q28-Z28 -> 80000 | AB28: OPAY | AC28: 7362914058 | AD28: XXY@GMAIL.COM | AE28: PENXXXXXXXXXXXX | AF28: UJHG1@ | AG28: 300000 | AH28: =LEN(AC28) -> 10 | AI28: =LEN(AE28) -> 15
... A41: =IF(B41="","",A40+1) -> 38 | B41: Afolabi Moruf Afuape | C41: CUSTOMER SERVICE REPRESENTATIVE | D41: OTL/0045 | E41: 45896 | F41: =$F$2 -> 45901 | G41: =$G$2 -> 45930 | H41: =G41-F41+1&" DAYS" -> 30 DAYS | I41: =30%*N41 -> 24000 | J41: =30%*N41 -> 24000 | K41: =20%*N41 -> 16000 | L41: =10%*N41 -> 8000 | M41: =10%*N41 -> 8000 | N41: =(80000/$F$1*(G41-F41+1)) -> 80000 | O41: 0 | P41: 0 | Q41: =SUM(N41:P41) -> 80000 | R41: 0 | S41: 0 | T41: 0 | U41: 0 | V41: 0 | W41: 0 | X41: 0 | Y41: N/A | Z41: =SUM(R41:X41) -> 0 | AA41: =Q41-Z41 -> 80000 | AB41: GUARANTY TRUST BANK PLC | AC41: 6574832190 | AD41: XXY@GMAIL.COM | AE41: PENXXXXXXXXXXXX | AF41: PASD8# | AG41: 300000 | AH41: =LEN(AC41) -> 10 | AI41: =LEN(AE41) -> 15
A42: =IF(B42="","",A41+1) -> 39 | B42: Agah Avia Musa | C42: CUSTOMER SERVICE REPRESENTATIVE | D42: OTL/0008 | E42: 45628 | F42: =$F$2 -> 45901 | G42: =$G$2 -> 45930 | H42: =G42-F42+1&" DAYS" -> 30 DAYS | I42: =30%*N42 -> 27000 | J42: =30%*N42 -> 27000 | K42: =20%*N42 -> 18000 | L42: =10%*N42 -> 9000 | M42: =10%*N42 -> 9000 | N42: =(90000/$F$1*(G42-F42+1)) -> 90000 | O42: =$O$1 -> 0 | P42: 0 | Q42: =SUM(N42:P42) -> 90000 | R42: 0 | S42: 0 | T42: 0 | U42: 0 | V42: 0 | W42: 0 | X42: 0 | Y42: N/A | Z42: =SUM(R42:X42) -> 0 | AA42: =Q42-Z42 -> 90000 | AB42: GUARANTY TRUST BANK PLC | AC42: 3847562109 | AD42: XXY@GMAIL.COM | AE42: PENXXXXXXXXXXXX | AF42: LOPK0& | AG42: 300000 | AH42: =LEN(AC42) -> 10 | AI42: =LEN(AE42) -> 15
A43: =IF(B43="","",A42+1) -> 40 | B43: Agbedi Yeitiemone Frederick | C43: CUSTOMER SERVICE REPRESENTATIVE | D43: OTL/0020 | E43: 45628 | F43: =$F$2 -> 45901 | G43: =$G$2 -> 45930 | H43: =G43-F43+1&" DAYS" -> 30 DAYS | I43: =30%*N43 -> 27000 | J43: =30%*N43 -> 27000 | K43: =20%*N43 -> 18000 | L43: =10%*N43 -> 9000 | M43: =10%*N43 -> 9000 | N43: =(90000/$F$1*(G43-F43+1)) -> 90000 | O43: =$O$1 -> 0 | P43: 0 | Q43: =SUM(N43:P43) -> 90000 | R43: 0 | S43: 0 | T43: 0 | U43: 0 | V43: 0 | W43: 0 | X43: 0 | Y43: N/A | Z43: =SUM(R43:X43) -> 0 | AA43: =Q43-Z43 -> 90000 | AB43: GUARANTY TRUST BANK PLC | AC43: 7461923058 | AD43: XXY@GMAIL.COM | AE43: PENXXXXXXXXXXXX | AF43: VBNM5^ | AG43: 300000 | AH43: =LEN(AC43) -> 10 | AI43: =LEN(AE43) -> 15
A44: =IF(B44="","",A43+1) -> 41 | B44: Ahmad Abdullahi Kalambaina | C44: QUALITY ASSURANCE OFFICER | D44: OTL/0024 | E44: 45244 | F44: =$F$2 -> 45901 | G44: 45926 | H44: =G44-F44+1&" DAYS" -> 26 DAYS | I44: =30%*N44 -> 37700 | J44: =30%*N44 -> 37700 | K44: =20%*N44 -> 25133.333 | L44: =10%*N44 -> 12566.667 | M44: =10%*N44 -> 12566.667 | N44: =(145000/$F$1*(G44-F44+1)) -> 125666.67 | O44: 0 | P44: 0 | Q44: =SUM(N44:P44) -> 125666.67 | R44: 0 | S44: 0 | T44: 0 | U44: 0 | V44: 0 | W44: 0 | X44: 0 | Y44: N/A | Z44: =SUM(R44:X44) -> 0 | AA44: =Q44-Z44 -> 125666.67 | AB44: UNION BANK | AC44: 5829307416 | AD44: XXY@GMAIL.COM | AE44: PENXXXXXXXXXXXX | AF44: RTYU3@ | AG44: 300000 | AH44: =LEN(AC44) -> 10 | AI44: =LEN(AE44) -> 15
A45: =IF(B45="","",A44+1) -> 42 | B45: Ahmadu Usman Jaha | C45: COMPLIANCE OFFICER | D45: OTL/0038 | E45: 45887 | F45: =$F$2 -> 45901 | G45: =$G$2 -> 45930 | H45: =G45-F45+1&" DAYS" -> 30 DAYS | I45: =30%*N45 -> 30000 | J45: =30%*N45 -> 30000 | K45: =20%*N45 -> 20000 | L45: =10%*N45 -> 10000 | M45: =10%*N45 -> 10000 | N45: =(100000/$F$1*(G45-F45+1)) -> 100000 | O45: =$O$1 -> 0 | P45: 0 | Q45: =SUM(N45:P45) -> 100000 | R45: 0 | S45: 0 | T45: 0 | U45: 0 | V45: 0 | W45: 0 | X45: 0 | Y45: N/A | Z45: =SUM(R45:X45) -> 0 | AA45: =Q45-Z45 -> 100000 | AB45: GUARANTY TRUST BANK PLC | AC45: 1092835476 | AD45: XXY@GMAIL.COM | AE45: PENXXXXXXXXXXXX | AF45: EIWO9# | AG45: 300000 | AH45: =LEN(AC45) -> 10 | AI45: =LEN(AE45) -> 15
A46: =IF(B46="","",A45+1) -> 43 | B46: Ahmed Adam Saba | C46: HEALTH & SAFETY OFFICER | D46: OTL/0002 | E46: 45691 | F46: =$F$2 -> 45901 | G46: =$G$2 -> 45930 | H46: =G46-F46+1&" DAYS" -> 30 DAYS | I46: =30%*N46 -> 81000 | J46: =30%*N46 -> 81000 | K46: =20%*N46 -> 54000 | L46: =10%*N46 -> 27000 | M46: =10%*N46 -> 27000 | N46: =(270000/$F$1*(G46-F46+1)) -> 270000 | O46: =$O$1 -> 0 | P46: 0 | Q46: =SUM(N46:P46) -> 270000 | R46: 0 | S46: 0 | T46: 0 | U46: 0 | V46: 0 | W46: 100000 | X46: 0 | Y46: N/A | Z46: =SUM(R46:X46) -> 100000 | AA46: =Q46-Z46 -> 170000 | AB46: GUARANTY TRUST BANK PLC | AC46: 8473629150 | AD46: XXY@GMAIL.COM | AE46: PENXXXXXXXXXXXX | AF46: UJHG2& | AG46: 300000 | AH46: =LEN(AC46) -> 10 | AI46: =LEN(AE46) -> 15
A47: =IF(B47="","",A46+1) -> 44 | B47: Ahmed Aliyu | C47: RESEARCH & DEVELOPMENT OFFICER | D47: OTL/0037 | E47: 45845 | F47: =$F$2 -> 45901 | G47: =$G$2 -> 45930 | H47: =G47-F47+1&" DAYS" -> 30 DAYS | I47: =30%*N47 -> 30000 | J47: =30%*N47 -> 30000 | K47: =20%*N47 -> 20000 | L47: =10%*N47 -> 10000 | M47: =10%*N47 -> 10000 | N47: =(100000/$F$1*(G47-F47+1)) -> 100000 | O47: =$O$1 -> 0 | P47: 0 | Q47: =SUM(N47:P47) -> 100000 | R47: 0 | S47: 0 | T47: 0 | U47: 0 | V47: 0 | W47: 0 | X47: 0 | Y47: N/A | Z47: =SUM(R47:X47) -> 0 | AA47: =Q47-Z47 -> 100000 | AB47: GUARANTY TRUST BANK PLC | AC47: 7461928305 | AD47: XXY@GMAIL.COM | AE47: PENXXXXXXXXXXXX | AF47: AZXC7^ | AG47: 300000 | AH47: =LEN(AC47) -> 10 | AI47: =LEN(AE47) -> 15
A48: =IF(B48="","",A47+1) -> 45 | B48: Ahmed Doro Yusuf | C48: DATA ANALYST | D48: OTL/0006 | E48: 45628 | F48: =$F$2 -> 45901 | G48: =$G$2 -> 45930 | H48: =G48-F48+1&" DAYS" -> 30 DAYS | I48: =30%*N48 -> 31500 | J48: =30%*N48 -> 31500 | K48: =20%*N48 -> 21000 | L48: =10%*N48 -> 10500 | M48: =10%*N48 -> 10500 | N48: =(105000/$F$1*(G48-F48+1)) -> 105000 | O48: =$O$1 -> 0 | P48: 0 | Q48: =SUM(N48:P48) -> 105000 | R48: 0 | S48: 0 | T48: 0 | U48: 0 | V48: 0 | W48: 0 | X48: 0 | Y48: N/A | Z48: =SUM(R48:X48) -> 0 | AA48: =Q48-Z48 -> 105000 | AB48: GUARANTY TRUST BANK PLC | AC48: 7461928305 | AD48: XXY@GMAIL.COM | AE48: PENXXXXXXXXXXXX | AF48: QWAS1@ | AG48: 300000 | AH48: =LEN(AC48) -> 10 | AI48: =LEN(AE48) -> 15
A49: =IF(B49="","",A48+1) -> 46 | B49: Ahmed Idris Wase | C49: PROJECT MANAGER | D49: OTL/0010 | E49: 45512 | F49: =$F$2 -> 45901 | G49: =$G$2 -> 45930 | H49: =G49-F49+1&" DAYS" -> 30 DAYS | I49: =30%*N49 -> 31500 | J49: =30%*N49 -> 31500 | K49: =20%*N49 -> 21000 | L49: =10%*N49 -> 10500 | M49: =10%*N49 -> 10500 | N49: =(105000/$F$1*(G49-F49+1)) -> 105000 | O49: =$O$1 -> 0 | P49: 0 | Q49: =SUM(N49:P49) -> 105000 | R49: 0 | S49: 0 | T49: 0 | U49: 0 | V49: 0 | W49: 10000 | X49: 0 | Y49: N/A | Z49: =SUM(R49:X49) -> 10000 | AA49: =Q49-Z49 -> 95000 | AB49: GUARANTY TRUST BANK PLC | AC49: 7461928305 | AD49: XXY@GMAIL.COM | AE49: PENXXXXXXXXXXXX | AF49: ERDF4# | AG49: 300000 | AH49: =LEN(AC49) -> 10 | AI49: =LEN(AE49) -> 15
A50: =IF(B50="","",A49+1) -> 47 | B50: Ahmed Munir | C50: BUSINESS DEVELOPMENT EXECUTIVE | D50: OTL/0056 | E50: 45896 | F50: =$F$2 -> 45901 | G50: =$G$2 -> 45930 | H50: =G50-F50+1&" DAYS" -> 30 DAYS | I50: =30%*N50 -> 30000 | J50: =30%*N50 -> 30000 | K50: =20%*N50 -> 20000 | L50: =10%*N50 -> 10000 | M50: =10%*N50 -> 10000 | N50: =(100000/$F$1*(G50-F50+1)) -> 100000 | O50: =$O$1 -> 0 | P50: 0 | Q50: =SUM(N50:P50) -> 100000 | R50: 0 | S50: 0 | T50: 0 | U50: 0 | V50: 0 | W50: 0 | X50: 0 | Y50: N/A | Z50: =SUM(R50:X50) -> 0 | AA50: =Q50-Z50 -> 100000 | AB50: GUARANTY TRUST BANK PLC | AC50: 7461928305 | AD50: XXY@GMAIL.COM | AE50: PENXXXXXXXXXXXX | AF50: TGYH6& | AG50: 300000 | AH50: =LEN(AC50) -> 10 | AI50: =LEN(AE50) -> 15
A51: =IF(B51="","",A50+1) -> 48 | B51: Ajilo Umar | C51: FACILITY MANAGER | D51: OTL/0021 | E51: 45579 | F51: =$F$2 -> 45901 | G51: =$G$2 -> 45930 | H51: =G51-F51+1&" DAYS" -> 30 DAYS | I51: =30%*N51 -> 24000 | J51: =30%*N51 -> 24000 | K51: =20%*N51 -> 16000 | L51: =10%*N51 -> 8000 | M51: =10%*N51 -> 8000 | N51: =(80000/$F$1*(G51-F51+1)) -> 80000 | O51: =$O$1 -> 0 | P51: 0 | Q51: =SUM(N51:P51) -> 80000 | R51: 0 | S51: 0 | T51: 0 | U51: 0 | V51: 0 | W51: 0 | X51: 0 | Y51: N/A | Z51: =SUM(R51:X51) -> 0 | AA51: =Q51-Z51 -> 80000 | AB51: ACCESS BANK | AC51: 7461928305 | AD51: XXY@GMAIL.COM | AE51: PENXXXXXXXXXXXX | AF51: ZXCV0^ | AG51: 300000 | AH51: =LEN(AC51) -> 10 | AI51: =LEN(AE51) -> 15
A52: =IF(B52="","",A51+1) -> 49 | B52: Akanni Enitan Dolapo-badru | C52: CLEANER | D52: OTL/0044 | E52: 45896 | F52: =$F$2 -> 45901 | G52: =$G$2 -> 45930 | H52: =G52-F52+1&" DAYS" -> 30 DAYS | I52: =30%*N52 -> 24000 | J52: =30%*N52 -> 24000 | K52: =20%*N52 -> 16000 | L52: =10%*N52 -> 8000 | M52: =10%*N52 -> 8000 | N52: =(80000/$F$1*(G52-F52+1)) -> 80000 | O52: =$O$1 -> 0 | P52: 0 | Q52: =SUM(N52:P52) -> 80000 | R52: 0 | S52: 0 | T52: 0 | U52: 0 | V52: 0 | W52: 0 | X52: 0 | Y52: N/A | Z52: =SUM(R52:X52) -> 0 | AA52: =Q52-Z52 -> 80000 | AB52: ACCESS BANK | AC52: 7461928305 | AD52: XXY@GMAIL.COM | AE52: PENXXXXXXXXXXXX | AF52: BNMM5@ | AG52: 300000 | AH52: =LEN(AC52) -> 10 | AI52: =LEN(AE52) -> 15
...

Sheet E-SLIP
C2: Payslip TRACTION OUTSOURCING NIGERIA LIMITED
C4: Employee name: | D4: =VLOOKUP($B$36,PAYROLL!A3:AF78,2,1) -> Abdullahi Dabai | E4: Emp ID | F4: =VLOOKUP($B$36,PAYROLL!$A$3:$AF$78,4,0) -> OTL/0005
E5: Start Date: | F5: =VLOOKUP($B$36,PAYROLL!$A$3:$AF$78,5,0) -> 45489
C6: Pay Period: | D6: =PAYROLL!C1 -> 45960 | E6: Designation: | F6: =VLOOKUP($B$36,PAYROLL!$A$3:$AF$78,3,0) -> HR MANAGER
C7: Worked Days: | D7: =VLOOKUP($B$36,PAYROLL!$A$3:$AF$78,8,0) -> 30 DAYS | E7: Bank: | F7: =VLOOKUP($B$36,PAYROLL!$A$3:$AF$78,28,0) -> ACCESS BANK
C8: Tax ID: | D8: =VLOOKUP($B$36,PAYROLL!$A$3:$AF$78,32,0) -> QRST8# | E8: Acc. Number: | F8: =VLOOKUP($B$36,PAYROLL!$A$3:$AF$78,29,0) -> 9182736450
C9: RSA Pin: | D9: =VLOOKUP($B$36,PAYROLL!$A$3:$AF$78,31,0) -> PENXXXXXXXXXXXX | E9: Email Address: | F9: =VLOOKUP($B$36,PAYROLL!$A$3:$AF$78,30,0) -> XXY@GMAIL.COM
C10: Earnings | D10: Amount | E10: Deductions | F10: Amount
C11: Basic | D11: =VLOOKUP($B$36,PAYROLL!$A$3:$AF$78,9,0) -> 81000 | E11: Staff Pension Contribution | F11: =VLOOKUP($B$36,PAYROLL!$A$3:$AF$78,18,0) -> 0
C12: Housing | D12: =VLOOKUP($B$36,PAYROLL!$A$3:$AF$78,10,0) -> 81000 | E12: Income Tax(PAYE) | F12: =VLOOKUP($B$36,PAYROLL!$A$3:$AF$78,19,0) -> ₦29,600.00
C13: Transport | D13: =VLOOKUP($B$36,PAYROLL!$A$3:$AF$78,11,0) -> 54000 | E13: Life Assurance | F13: =VLOOKUP($B$36,PAYROLL!$A$3:$AF$78,20,0) -> 0
C14: Utility Allowance | D14: =VLOOKUP($B$36,PAYROLL!$A$3:$AF$78,12,0) -> 27000 | E14: NHF | F14: =VLOOKUP($B$36,PAYROLL!$A$3:$AF$78,21,0) -> 0
C15: Meal | D15: =VLOOKUP($B$36,PAYROLL!$A$3:$AF$78,13,0) -> 27000 | E15: Other Deductions | F15: =VLOOKUP($B$36,PAYROLL!$A$3:$AF$78,22,0) -> 0
C16: SUB TOTAL | D16: =SUM(D11:D15) -> 270000 | E16: Loan Repayment | F16: =VLOOKUP($B$36,PAYROLL!$A$3:$AF$78,23,0) -> 0
C17: Bonus | D17: =VLOOKUP($B$36,PAYROLL!$A$3:$AF$78,15,0) -> 0 | E17: Penalty | F17: =VLOOKUP($B$36,PAYROLL!$A$3:$AF$78,24,0) -> 0
C18: Perfomance Reward | D18: =VLOOKUP($B$36,PAYROLL!$A$3:$AF$78,16,0) -> 0 | E18: Reason | F18: =VLOOKUP($B$36,PAYROLL!$A$3:$AF$78,25,0) -> N/A
C19: Total Earnings | D19: =SUM(D16:D18) -> 270000 | E19: Total Deductions | F19: =SUM(F11:F18) -> 0
C21: Net Pay
C22: =ROUND(D19-F19, 2) -> 270000
C23: =PROPER(MONEYTEXT(C22,"NGN")) -> #NAME?
C26: Employer Signature | E26: Employee Signature
C32: This is a system generated payslip
B36: =PAYROLL!A1 -> 6

Sheet OLD PAYE
T1: =T7-U6 -> 1926112 | U1: =T1-300000 -> 1626112 | V1: =U1-500000 -> 1126112 | W1: =V1-500000 -> 626112 | X1: =21%*W1 -> 131483.52
B3: Staff Details | F3: Gross Emolument Breakdown | L3: Statutory Deductions | Q3: Chargeble Income | U3: PAYE Tax Band
F4: 0.3 | G4: 0.3 | H4: 0.2 | I4: 0.1 | J4: 0.1 | L4: 0.08 | M4: 0.05 | N4: 0.025 | R4: 12 | U4: 0.07 | V4: 0.11 | W4: 0.15 | X4: 0.19 | Y4: 0.21 | Z4: 0.24 | AA4: Annual PAYE | AB4: Monthly PAYE | AC4: Monthly Net Pay | AD4: 0.1
K5: =270000-L7 -> 252720 | L5: =K5*12 -> 3032640 | Q5: =1%*R7+20%*R7 -> 636854.4 | R5: =200000+20%*R7 -> 806528 | U5: First | V5: Next | W5: Next | X5: Next | Y5: Next | Z5: Next
B6: S/N | C6: Name | D6: Staff ID | E6: Employee Gross Income | F6: BASIC | G6: HOUSING | H6: TRANSPORT | I6: UTILITY | J6: MEAL | K6: Gross Income 1 | L6: Employee Pension 8% of BTH | M6: NHIS 5% of basic salary | N6: NHF 2.5% of Gross Income | O6: Leave Allowance | Q6: 13th Month/L.A/Bonus | R6: Gross Income 2 (Annual Income less statutory deductions) | S6: Consolidated Relief Allowance (CRA) | T6: Taxable Income | U6: 300000 | V6: 300000 | W6: 500000 | X6: 500000 | Y6: 1600000 | Z6: 3200000 | AD6: Employer's Pension Contribution 10% | AE6: ITF LEVY MONTHLY
B7: 1 | C7: SALIU AMINU | D7: OTL/0009 | E7: 270000 | F7: =E7*$F$4 -> 81000 | G7: =$G$4*E7 -> 81000 | H7: =$H$4*E7 -> 54000 | I7: =$I$4*E7 -> 27000 | J7: =$J$4*E7 -> 27000 | K7: =SUM(F7:J7) -> 270000 | L7: =$L$4*(F7+G7+H7) -> 17280 | R7: =$R$4*(K7-L7-M7-N7) -> 3032640 | S7: =IF(1%*R7<200000,200000+(20%*R7),(1%*R7)+(20%*R7)) -> 806528 | T7: =R7-S7 -> 2226112 | U7: =IF(T7<$U$6,1%*T7,IF(T7>$U$6,$U$4*$U$6)) -> 21000 | V7: =IF(T7-300000>+$V$6,$V$4*$V$6,IF(T7-300000<0,"-",$V$4*(T7-300000))) -> 33000 | W7: =IF(T7-600000>=$W$6,$W$4*$W$6,IF(T7-600000<0,"-",$W$4*(T7-600000))) -> 75000 | X7: =IF(T7-1100000>=$X$6,$X$4*$X$6,IF(T7-1100000<0,"-",$X$4*(T7-1100000))) -> 95000 | Y7: =IF(T7-1600000>=$Y$6,$Y$4*$Y$6,IF(T7-1600000<0,"-",$Y$4*(T7-1600000))) -> 131483.52 | Z7: =IF(T7-3200000>0,$Z$4*(T7-3200000),"-") -> - | AA7: =SUM(U7:Z7) -> 355483.52 | AB7: =AA7/12 -> 29623.627 | AC7: =K7-L7-M7-N7-AB7 -> 223096.37 | AD7: =(F7+G7+H7)*$AD$4 -> 21600 | AE7: 1475
B8: =IF(C8="","",B7+1) -> 2 | C8: OLUDAYO BANKE | D8: OTL/0036 | E8: 330000 | F8: =E8*$F$4 -> 99000 | G8: =$G$4*E8 -> 99000 | H8: =$H$4*E8 -> 66000 | I8: =$I$4*E8 -> 33000 | J8: =$J$4*E8 -> 33000 | K8: =SUM(F8:J8) -> 330000 | L8: =$L$4*(F8+G8+H8) -> 21120 | R8: =$R$4*(K8-L8-M8-N8) -> 3706560 | S8: =IF(1%*R8<200000,200000+(20%*R8),(1%*R8)+(20%*R8)) -> 941312 | T8: =R8-S8 -> 2765248 | U8: =IF(T8<$U$6,1%*T8,IF(T8>$U$6,$U$4*$U$6)) -> 21000 | V8: =IF(T8-300000>+$V$6,$V$4*$V$6,IF(T8-300000<0,"-",$V$4*(T8-300000))) -> 33000 | W8: =IF(T8-600000>=$W$6,$W$4*$W$6,IF(T8-600000<0,"-",$W$4*(T8-600000))) -> 75000 | X8: =IF(T8-1100000>=$X$6,$X$4*$X$6,IF(T8-1100000<0,"-",$X$4*(T8-1100000))) -> 95000 | Y8: =IF(T8-1600000>=$Y$6,$Y$4*$Y$6,IF(T8-1600000<0,"-",$Y$4*(T8-1600000))) -> 244702.08 | Z8: =IF(T8-3200000>0,$Z$4*(T8-3200000),"-") -> - | AA8: =SUM(U8:Z8) -> 468702.08 | AB8: =AA8/12 -> 39058.507 | AC8: =K8-L8-M8-N8-AB8 -> 269821.49 | AD8: =(F8+G8+H8)*$AD$4 -> 26400 | AE8: =(AC8-82500)*10% -> 18732.149
B9: =IF(C9="","",B8+1) -> 3 | C9: CHRISTOPHER HANNAH | D9: OTL/0058 | E9: 500000 | F9: =E9*$F$4 -> 150000 | G9: =$G$4*E9 -> 150000 | H9: =$H$4*E9 -> 100000 | I9: =$I$4*E9 -> 50000 | J9: =$J$4*E9 -> 50000 | K9: =SUM(F9:J9) -> 500000 | L9: =$L$4*(F9+G9+H9) -> 32000 | R9: =$R$4*(K9-L9-M9-N9) -> 5616000 | S9: =IF(1%*R9<200000,200000+(20%*R9),(1%*R9)+(20%*R9)) -> 1323200 | T9: =R9-S9 -> 4292800 | U9: =IF(T9<$U$6,1%*T9,IF(T9>$U$6,$U$4*$U$6)) -> 21000 | V9: =IF(T9-300000>+$V$6,$V$4*$V$6,IF(T9-300000<0,"-",$V$4*(T9-300000))) -> 33000 | W9: =IF(T9-600000>=$W$6,$W$4*$W$6,IF(T9-600000<0,"-",$W$4*(T9-600000))) -> 75000 | X9: =IF(T9-1100000>=$X$6,$X$4*$X$6,IF(T9-1100000<0,"-",$X$4*(T9-1100000))) -> 95000 | Y9: =IF(T9-1600000>=$Y$6,$Y$4*$Y$6,IF(T9-1600000<0,"-",$Y$4*(T9-1600000))) -> 336000 | Z9: =IF(T9-3200000>0,$Z$4*(T9-3200000),"-") -> 262272 | AA9: =SUM(U9:Z9) -> 822272 | AB9: =AA9/12 -> 68522.667 | AC9: =K9-L9-M9-N9-AB9 -> 399477.33 | AD9: =(F9+G9+H9)*$AD$4 -> 40000 | AE9: 3493
B10: =IF(C10="","",B9+1) -> 4 | C10: OJO ABIGAIL | D10: OTL/0014 | E10: 500000 | F10: =E10*$F$4 -> 150000 | G10: =$G$4*E10 -> 150000 | H10: =$H$4*E10 -> 100000 | I10: =$I$4*E10 -> 50000 | J10: =$J$4*E10 -> 50000 | K10: =SUM(F10:J10) -> 500000 | L10: =$L$4*(F10+G10+H10) -> 32000 | R10: =$R$4*(K10-L10-M10-N10) -> 5616000 | S10: =IF(1%*R10<200000,200000+(20%*R10),(1%*R10)+(20%*R10)) -> 1323200 | T10: =R10-S10 -> 4292800 | U10: =IF(T10<$U$6,1%*T10,IF(T10>$U$6,$U$4*$U$6)) -> 21000 | V10: =IF(T10-300000>+$V$6,$V$4*$V$6,IF(T10-300000<0,"-",$V$4*(T10-300000))) -> 33000 | W10: =IF(T10-600000>=$W$6,$W$4*$W$6,IF(T10-600000<0,"-",$W$4*(T10-600000))) -> 75000 | X10: =IF(T10-1100000>=$X$6,$X$4*$X$6,IF(T10-1100000<0,"-",$X$4*(T10-1100000))) -> 95000 | Y10: =IF(T10-1600000>=$Y$6,$Y$4*$Y$6,IF(T10-1600000<0,"-",$Y$4*(T10-1600000))) -> 336000 | Z10: =IF(T10-3200000>0,$Z$4*(T10-3200000),"-") -> 262272 | AA10: =SUM(U10:Z10) -> 822272 | AB10: =AA10/12 -> 68522.667 | AC10: =K10-L10-M10-N10-AB10 -> 399477.33 | AD10: =(F10+G10+H10)*$AD$4 -> 40000 | AE10: 3493
B11: =IF(C11="","",B10+1) -> 5 | C11: Abdulkadir Rahis | D11: OTL/0032 | E11: 500000 | F11: =E11*$F$4 -> 150000 | G11: =$G$4*E11 -> 150000 | H11: =$H$4*E11 -> 100000 | I11: =$I$4*E11 -> 50000 | J11: =$J$4*E11 -> 50000 | K11: =SUM(F11:J11) -> 500000 | L11: =$L$4*(F11+G11+H11) -> 32000 | R11: =$R$4*(K11-L11-M11-N11) -> 5616000 | S11: =IF(1%*R11<200000,200000+(20%*R11),(1%*R11)+(20%*R11)) -> 1323200 | T11: =R11-S11 -> 4292800 | U11: =IF(T11<$U$6,1%*T11,IF(T11>$U$6,$U$4*$U$6)) -> 21000 | V11: =IF(T11-300000>+$V$6,$V$4*$V$6,IF(T11-300000<0,"-",$V$4*(T11-300000))) -> 33000 | W11: =IF(T11-600000>=$W$6,$W$4*$W$6,IF(T11-600000<0,"-",$W$4*(T11-600000))) -> 75000 | X11: =IF(T11-1100000>=$X$6,$X$4*$X$6,IF(T11-1100000<0,"-",$X$4*(T11-1100000))) -> 95000 | Y11: =IF(T11-1600000>=$Y$6,$Y$4*$Y$6,IF(T11-1600000<0,"-",$Y$4*(T11-1600000))) -> 336000 | Z11: =IF(T11-3200000>0,$Z$4*(T11-3200000),"-") -> 262272 | AA11: =SUM(U11:Z11) -> 822272 | AB11: =AA11/12 -> 68522.667 | AC11: =K11-L11-M11-N11-AB11 -> 399477.33 | AD11: =(F11+G11+H11)*$AD$4 -> 40000 | AE11: 3493
B12: =IF(C12="","",B11+1) -> 6 | C12: Abdullahi Dabai | D12: OTL/0005 | E12: 500000 | F12: =E12*$F$4 -> 150000 | G12: =$G$4*E12 -> 150000 | H12: =$H$4*E12 -> 100000 | I12: =$I$4*E12 -> 50000 | J12: =$J$4*E12 -> 50000 | K12: =SUM(F12:J12) -> 500000 | L12: =$L$4*(F12+G12+H12) -> 32000 | R12: =$R$4*(K12-L12-M12-N12) -> 5616000 | S12: =IF(1%*R12<200000,200000+(20%*R12),(1%*R12)+(20%*R12)) -> 1323200 | T12: =R12-S12 -> 4292800 | U12: =IF(T12<$U$6,1%*T12,IF(T12>$U$6,$U$4*$U$6)) -> 21000 | V12: =IF(T12-300000>+$V$6,$V$4*$V$6,IF(T12-300000<0,"-",$V$4*(T12-300000))) -> 33000 | W12: =IF(T12-600000>=$W$6,$W$4*$W$6,IF(T12-600000<0,"-",$W$4*(T12-600000))) -> 75000 | X12: =IF(T12-1100000>=$X$6,$X$4*$X$6,IF(T12-1100000<0,"-",$X$4*(T12-1100000))) -> 95000 | Y12: =IF(T12-1600000>=$Y$6,$Y$4*$Y$6,IF(T12-1600000<0,"-",$Y$4*(T12-1600000))) -> 336000 | Z12: =IF(T12-3200000>0,$Z$4*(T12-3200000),"-") -> 262272 | AA12: =SUM(U12:Z12) -> 822272 | AB12: =AA12/12 -> 68522.667 | AC12: =K12-L12-M12-N12-AB12 -> 399477.33 | AD12: =(F12+G12+H12)*$AD$4 -> 40000 | AE12: 3493
B13: =IF(C13="","",B12+1) -> 7 | C13: Abdullahi Idris Garba | D13: OTL/0013 | E13: 500000 | F13: =E13*$F$4 -> 150000 | G13: =$G$4*E13 -> 150000 | H13: =$H$4*E13 -> 100000 | I13: =$I$4*E13 -> 50000 | J13: =$J$4*E13 -> 50000 | K13: =SUM(F13:J13) -> 500000 | L13: =$L$4*(F13+G13+H13) -> 32000 | R13: =$R$4*(K13-L13-M13-N13) -> 5616000 | S13: =IF(1%*R13<200000,200000+(20%*R13),(1%*R13)+(20%*R13)) -> 1323200 | T13: =R13-S13 -> 4292800 | U13: =IF(T13<$U$6,1%*T13,IF(T13>$U$6,$U$4*$U$6)) -> 21000 | V13: =IF(T13-300000>+$V$6,$V$4*$V$6,IF(T13-300000<0,"-",$V$4*(T13-300000))) -> 33000 | W13: =IF(T13-600000>=$W$6,$W$4*$W$6,IF(T13-600000<0,"-",$W$4*(T13-600000))) -> 75000 | X13: =IF(T13-1100000>=$X$6,$X$4*$X$6,IF(T13-1100000<0,"-",$X$4*(T13-1100000))) -> 95000 | Y13: =IF(T13-1600000>=$Y$6,$Y$4*$Y$6,IF(T13-1600000<0,"-",$Y$4*(T13-1600000))) -> 336000 | Z13: =IF(T13-3200000>0,$Z$4*(T13-3200000),"-") -> 262272 | AA13: =SUM(U13:Z13) -> 822272 | AB13: =AA13/12 -> 68522.667 | AC13: =K13-L13-M13-N13-AB13 -> 399477.33 | AD13: =(F13+G13+H13)*$AD$4 -> 40000 | AE13: 3493
B14: =IF(C14="","",B13+1) -> 8 | C14: Abdullahi Mamudu | D14: OTL/0016 | E14: 500000 | F14: =E14*$F$4 -> 150000 | G14: =$G$4*E14 -> 150000 | H14: =$H$4*E14 -> 100000 | I14: =$I$4*E14 -> 50000 | J14: =$J$4*E14 -> 50000 | K14: =SUM(F14:J14) -> 500000 | L14: =$L$4*(F14+G14+H14) -> 32000 | R14: =$R$4*(K14-L14-M14-N14) -> 5616000 | S14: =IF(1%*R14<200000,200000+(20%*R14),(1%*R14)+(20%*R14)) -> 1323200 | T14: =R14-S14 -> 4292800 | U14: =IF(T14<$U$6,1%*T14,IF(T14>$U$6,$U$4*$U$6)) -> 21000 | V14: =IF(T14-300000>+$V$6,$V$4*$V$6,IF(T14-300000<0,"-",$V$4*(T14-300000))) -> 33000 | W14: =IF(T14-600000>=$W$6,$W$4*$W$6,IF(T14-600000<0,"-",$W$4*(T14-600000))) -> 75000 | X14: =IF(T14-1100000>=$X$6,$X$4*$X$6,IF(T14-1100000<0,"-",$X$4*(T14-1100000))) -> 95000 | Y14: =IF(T14-1600000>=$Y$6,$Y$4*$Y$6,IF(T14-1600000<0,"-",$Y$4*(T14-1600000))) -> 336000 | Z14: =IF(T14-3200000>0,$Z$4*(T14-3200000),"-") -> 262272 | AA14: =SUM(U14:Z14) -> 822272 | AB14: =AA14/12 -> 68522.667 | AC14: =K14-L14-M14-N14-AB14 -> 399477.33 | AD14: =(F14+G14+H14)*$AD$4 -> 40000 | AE14: 3493
B15: =IF(C15="","",B14+1) -> 9 | C15: Abdullahi Sani | D15: OTL/0017 | E15: 500000 | F15: =E15*$F$4 -> 150000 | G15: =$G$4*E15 -> 150000 | H15: =$H$4*E15 -> 100000 | I15: =$I$4*E15 -> 50000 | J15: =$J$4*E15 -> 50000 | K15: =SUM(F15:J15) -> 500000 | L15: =$L$4*(F15+G15+H15) -> 32000 | R15: =$R$4*(K15-L15-M15-N15) -> 5616000 | S15: =IF(1%*R15<200000,200000+(20%*R15),(1%*R15)+(20%*R15)) -> 1323200 | T15: =R15-S15 -> 4292800 | U15: =IF(T15<$U$6,1%*T15,IF(T15>$U$6,$U$4*$U$6)) -> 21000 | V15: =IF(T15-300000>+$V$6,$V$4*$V$6,IF(T15-300000<0,"-",$V$4*(T15-300000))) -> 33000 | W15: =IF(T15-600000>=$W$6,$W$4*$W$6,IF(T15-600000<0,"-",$W$4*(T15-600000))) -> 75000 | X15: =IF(T15-1100000>=$X$6,$X$4*$X$6,IF(T15-1100000<0,"-",$X$4*(T15-1100000))) -> 95000 | Y15: =IF(T15-1600000>=$Y$6,$Y$4*$Y$6,IF(T15-1600000<0,"-",$Y$4*(T15-1600000))) -> 336000 | Z15: =IF(T15-3200000>0,$Z$4*(T15-3200000),"-") -> 262272 | AA15: =SUM(U15:Z15) -> 822272 | AB15: =AA15/12 -> 68522.667 | AC15: =K15-L15-M15-N15-AB15 -> 399477.33 | AD15: =(F15+G15+H15)*$AD$4 -> 40000 | AE15: 3493
B16: =IF(C16="","",B15+1) -> 10 | C16: Abdulmalik Zubairu | D16: OTL/0007 | E16: 500000 | F16: =E16*$F$4 -> 150000 | G16: =$G$4*E16 -> 150000 | H16: =$H$4*E16 -> 100000 | I16: =$I$4*E16 -> 50000 | J16: =$J$4*E16 -> 50000 | K16: =SUM(F16:J16) -> 500000 | L16: =$L$4*(F16+G16+H16) -> 32000 | R16: =$R$4*(K16-L16-M16-N16) -> 5616000 | S16: =IF(1%*R16<200000,200000+(20%*R16),(1%*R16)+(20%*R16)) -> 1323200 | T16: =R16-S16 -> 4292800 | U16: =IF(T16<$U$6,1%*T16,IF(T16>$U$6,$U$4*$U$6)) -> 21000 | V16: =IF(T16-300000>+$V$6,$V$4*$V$6,IF(T16-300000<0,"-",$V$4*(T16-300000))) -> 33000 | W16: =IF(T16-600000>=$W$6,$W$4*$W$6,IF(T16-600000<0,"-",$W$4*(T16-600000))) -> 75000 | X16: =IF(T16-1100000>=$X$6,$X$4*$X$6,IF(T16-1100000<0,"-",$X$4*(T16-1100000))) -> 95000 | Y16: =IF(T16-1600000>=$Y$6,$Y$4*$Y$6,IF(T16-1600000<0,"-",$Y$4*(T16-1600000))) -> 336000 | Z16: =IF(T16-3200000>0,$Z$4*(T16-3200000),"-") -> 262272 | AA16: =SUM(U16:Z16) -> 822272 | AB16: =AA16/12 -> 68522.667 | AC16: =K16-L16-M16-N16-AB16 -> 399477.33 | AD16: =(F16+G16+H16)*$AD$4 -> 40000 | AE16: 3493
B17: =IF(C17="","",B16+1) -> 11 | C17: Abdulmumin Ari Mohammed | D17: OTL/0004 | E17: 500000 | F17: =E17*$F$4 -> 150000 | G17: =$G$4*E17 -> 150000 | H17: =$H$4*E17 -> 100000 | I17: =$I$4*E17 -> 50000 | J17: =$J$4*E17 -> 50000 | K17: =SUM(F17:J17) -> 500000 | L17: =$L$4*(F17+G17+H17) -> 32000 | R17: =$R$4*(K17-L17-M17-N17) -> 5616000 | S17: =IF(1%*R17<200000,200000+(20%*R17),(1%*R17)+(20%*R17)) -> 1323200 | T17: =R17-S17 -> 4292800 | U17: =IF(T17<$U$6,1%*T17,IF(T17>$U$6,$U$4*$U$6)) -> 21000 | V17: =IF(T17-300000>+$V$6,$V$4*$V$6,IF(T17-300000<0,"-",$V$4*(T17-300000))) -> 33000 | W17: =IF(T17-600000>=$W$6,$W$4*$W$6,IF(T17-600000<0,"-",$W$4*(T17-600000))) -> 75000 | X17: =IF(T17-1100000>=$X$6,$X$4*$X$6,IF(T17-1100000<0,"-",$X$4*(T17-1100000))) -> 95000 | Y17: =IF(T17-1600000>=$Y$6,$Y$4*$Y$6,IF(T17-1600000<0,"-",$Y$4*(T17-1600000))) -> 336000 | Z17: =IF(T17-3200000>0,$Z$4*(T17-3200000),"-") -> 262272 | AA17: =SUM(U17:Z17) -> 822272 | AB17: =AA17/12 -> 68522.667 | AC17: =K17-L17-M17-N17-AB17 -> 399477.33 | AD17: =(F17+G17+H17)*$AD$4 -> 40000 | AE17: 3493
B18: =IF(C18="","",B17+1) -> 12 | C18: Abdulraheem Abdulmaleek | D18: OTL/0003 | E18: 500000 | F18: =E18*$F$4 -> 150000 | G18: =$G$4*E18 -> 150000 | H18: =$H$4*E18 -> 100000 | I18: =$I$4*E18 -> 50000 | J18: =$J$4*E18 -> 50000 | K18: =SUM(F18:J18) -> 500000 | L18: =$L$4*(F18+G18+H18) -> 32000 | R18: =$R$4*(K18-L18-M18-N18) -> 5616000 | S18: =IF(1%*R18<200000,200000+(20%*R18),(1%*R18)+(20%*R18)) -> 1323200 | T18: =R18-S18 -> 4292800 | U18: =IF(T18<$U$6,1%*T18,IF(T18>$U$6,$U$4*$U$6)) -> 21000 | V18: =IF(T18-300000>+$V$6,$V$4*$V$6,IF(T18-300000<0,"-",$V$4*(T18-300000))) -> 33000 | W18: =IF(T18-600000>=$W$6,$W$4*$W$6,IF(T18-600000<0,"-",$W$4*(T18-600000))) -> 75000 | X18: =IF(T18-1100000>=$X$6,$X$4*$X$6,IF(T18-1100000<0,"-",$X$4*(T18-1100000))) -> 95000 | Y18: =IF(T18-1600000>=$Y$6,$Y$4*$Y$6,IF(T18-1600000<0,"-",$Y$4*(T18-1600000))) -> 336000 | Z18: =IF(T18-3200000>0,$Z$4*(T18-3200000),"-") -> 262272 | AA18: =SUM(U18:Z18) -> 822272 | AB18: =AA18/12 -> 68522.667 | AC18: =K18-L18-M18-N18-AB18 -> 399477.33 | AD18: =(F18+G18+H18)*$AD$4 -> 40000 | AE18: 3493
B19: =IF(C19="","",B18+1) -> 13 | C19: Abdulraheem Olatunji Olawuyi | D19: OTL/0027 | E19: 500000 | F19: =E19*$F$4 -> 150000 | G19: =$G$4*E19 -> 150000 | H19: =$H$4*E19 -> 100000 | I19: =$I$4*E19 -> 50000 | J19: =$J$4*E19 -> 50000 | K19: =SUM(F19:J19) -> 500000 | L19: =$L$4*(F19+G19+H19) -> 32000 | R19: =$R$4*(K19-L19-M19-N19) -> 5616000 | S19: =IF(1%*R19<200000,200000+(20%*R19),(1%*R19)+(20%*R19)) -> 1323200 | T19: =R19-S19 -> 4292800 | U19: =IF(T19<$U$6,1%*T19,IF(T19>$U$6,$U$4*$U$6)) -> 21000 | V19: =IF(T19-300000>+$V$6,$V$4*$V$6,IF(T19-300000<0,"-",$V$4*(T19-300000))) -> 33000 | W19: =IF(T19-600000>=$W$6,$W$4*$W$6,IF(T19-600000<0,"-",$W$4*(T19-600000))) -> 75000 | X19: =IF(T19-1100000>=$X$6,$X$4*$X$6,IF(T19-1100000<0,"-",$X$4*(T19-1100000))) -> 95000 | Y19: =IF(T19-1600000>=$Y$6,$Y$4*$Y$6,IF(T19-1600000<0,"-",$Y$4*(T19-1600000))) -> 336000 | Z19: =IF(T19-3200000>0,$Z$4*(T19-3200000),"-") -> 262272 | AA19: =SUM(U19:Z19) -> 822272 | AB19: =AA19/12 -> 68522.667 | AC19: =K19-L19-M19-N19-AB19 -> 399477.33 | AD19: =(F19+G19+H19)*$AD$4 -> 40000 | AE19: 3493
B20: =IF(C20="","",B19+1) -> 14 | C20: Abiodun James Faleke | D20: OTL/0028 | E20: 500000 | F20: =E20*$F$4 -> 150000 | G20: =$G$4*E20 -> 150000 | H20: =$H$4*E20 -> 100000 | I20: =$I$4*E20 -> 50000 | J20: =$J$4*E20 -> 50000 | K20: =SUM(F20:J20) -> 500000 | L20: =$L$4*(F20+G20+H20) -> 32000 | R20: =$R$4*(K20-L20-M20-N20) -> 5616000 | S20: =IF(1%*R20<200000,200000+(20%*R20),(1%*R20)+(20%*R20)) -> 1323200 | T20: =R20-S20 -> 4292800 | U20: =IF(T20<$U$6,1%*T20,IF(T20>$U$6,$U$4*$U$6)) -> 21000 | V20: =IF(T20-300000>+$V$6,$V$4*$V$6,IF(T20-300000<0,"-",$V$4*(T20-300000))) -> 33000 | W20: =IF(T20-600000>=$W$6,$W$4*$W$6,IF(T20-600000<0,"-",$W$4*(T20-600000))) -> 75000 | X20: =IF(T20-1100000>=$X$6,$X$4*$X$6,IF(T20-1100000<0,"-",$X$4*(T20-1100000))) -> 95000 | Y20: =IF(T20-1600000>=$Y$6,$Y$4*$Y$6,IF(T20-1600000<0,"-",$Y$4*(T20-1600000))) -> 336000 | Z20: =IF(T20-3200000>0,$Z$4*(T20-3200000),"-") -> 262272 | AA20: =SUM(U20:Z20) -> 822272 | AB20: =AA20/12 -> 68522.667 | AC20: =K20-L20-M20-N20-AB20 -> 399477.33 | AD20: =(F20+G20+H20)*$AD$4 -> 40000 | AE20: 3493
... B56: =IF(C56="","",B55+1) -> 50 | C56: Akeem Adeniyi Adeyemi | D56: OTL/0057 | E56: 500000 | F56: =E56*$F$4 -> 150000 | G56: =$G$4*E56 -> 150000 | H56: =$H$4*E56 -> 100000 | I56: =$I$4*E56 -> 50000 | J56: =$J$4*E56 -> 50000 | K56: =SUM(F56:J56) -> 500000 | L56: =$L$4*(F56+G56+H56) -> 32000 | R56: =$R$4*(K56-L56-M56-N56) -> 5616000 | S56: =IF(1%*R56<200000,200000+(20%*R56),(1%*R56)+(20%*R56)) -> 1323200 | T56: =R56-S56 -> 4292800 | U56: =IF(T56<$U$6,1%*T56,IF(T56>$U$6,$U$4*$U$6)) -> 21000 | V56: =IF(T56-300000>+$V$6,$V$4*$V$6,IF(T56-300000<0,"-",$V$4*(T56-300000))) -> 33000 | W56: =IF(T56-600000>=$W$6,$W$4*$W$6,IF(T56-600000<0,"-",$W$4*(T56-600000))) -> 75000 | X56: =IF(T56-1100000>=$X$6,$X$4*$X$6,IF(T56-1100000<0,"-",$X$4*(T56-1100000))) -> 95000 | Y56: =IF(T56-1600000>=$Y$6,$Y$4*$Y$6,IF(T56-1600000<0,"-",$Y$4*(T56-1600000))) -> 336000 | Z56: =IF(T56-3200000>0,$Z$4*(T56-3200000),"-") -> 262272 | AA56: =SUM(U56:Z56) -> 822272 | AB56: =AA56/12 -> 68522.667 | AC56: =K56-L56-M56-N56-AB56 -> 399477.33 | AD56: =(F56+G56+H56)*$AD$4 -> 40000 | AE56: 3493
D57: OTL/0035
D58: OTL/0040
D59: OTL/0039
D60: OTL/0001
D61: OTL/0029
D62: OTL/0023
D63: OTL/0030
D64: OTL/0060
D65: OTL/0062
D66: OTL/0061
D67: OTL/0059
D68: OTL/0063

Sheet PAYE SHORT
A1: XYZ LIMITED
A2: 2 KAJOLA STREET, OPP ST TIGER LAGOS
A3: 2022 REVIEW STAFF PAYROLL AND TAX PAYABLE
A4: SN | B4: NAME | C4: DEPT | D4: SALARY | E4: ANNUAL SALARY | F4: PENSION | G4: NHF | H4: GROSS INCOME | I4: CRA | J4: TAXABLE INCOME | K4: ANNUAL TAX | L4: MONTHLY TAX
A5: 1 | B5: TAIWO | C5: ACC | D5: 50000 | E5: 5189992.7 | F5: =8%*E5 -> 415199.42 | G5: =2.5%*E5 -> 129749.82 | H5: =+E5-F5-G5 -> 4645043.5 | I5: =IF(1%*H5>200000,(1%*H5)+20%*H5,200000+20%*H5) -> 1129008.7 | J5: =+H5-I5 -> 3516034.8 | K5: =IF(J5<=300000,7%*J5,IF(AND(J5>300000,J5<=600000),21000+(J5-300000)*11%,IF(AND(J5>600000,J5<=1100000),54000+(J5-600000)*15%,IF(AND(J5>1100000,J5<=1600000),129000+(J5-1100000)*19%,IF(AND(J5>1600000,J5<=3200000),224000+(J5-1600000)*21%,560000+(J5-3200000)*24%))))) -> 635848.35 | L5: =+K5/12 -> 52987.363 | M5: =(E5/12)-L5-(F5/12) -> 344912.08
A6: 2 | B6: JIDE | C6: COST | D6: 100000 | E6: =+D6*12 -> 1200000 | F6: =8%*E6 -> 96000 | G6: =2.5%*E6 -> 30000 | H6: =+E6-F6-G6 -> 1074000 | I6: =IF(1%*H6>200000,(1%*H6)+20%*H6,200000+20%*H6) -> 414800 | J6: =+H6-I6 -> 659200 | K6: =IF(J6<=300000,7%*J6,IF(AND(J6>300000,J6<=600000),21000+(J6-300000)*11%,IF(AND(J6>600000,J6<=1100000),54000+(J6-600000)*15%,IF(AND(J6>1100000,J6<=1600000),129000+(J6-1100000)*19%,IF(AND(J6>1600000,J6<=3200000),224000+(J6-1600000)*21%,560000+(J6-3200000)*24%))))) -> 62880 | L6: =+K6/12 -> 5240
A7: 3 | B7: FEMI | C7: HR | D7: 50000 | E7: =+D7*12 -> 600000 | F7: =8%*E7 -> 48000 | G7: =2.5%*E7 -> 15000 | H7: =+E7-F7-G7 -> 537000 | I7: =IF(1%*H7>200000,(1%*H7)+20%*H7,200000+20%*H7) -> 307400 | J7: =+H7-I7 -> 229600 | K7: =IF(J7<=300000,7%*J7,IF(AND(J7>300000,J7<=600000),21000+(J7-300000)*11%,IF(AND(J7>600000,J7<=1100000),54000+(J7-600000)*15%,IF(AND(J7>1100000,J7<=1600000),129000+(J7-1100000)*19%,IF(AND(J7>1600000,J7<=3200000),224000+(J7-1600000)*21%,560000+(J7-3200000)*24%))))) -> 16072 | L7: =+K7/12 -> 1339.3333
A8: 4 | B8: EMMANUEL | C8: PRD | D8: 120000 | E8: =+D8*12 -> 1440000 | F8: =8%*E8 -> 115200 | G8: =2.5%*E8 -> 36000 | H8: =+E8-F8-G8 -> 1288800 | I8: =IF(1%*H8>200000,(1%*H8)+20%*H8,200000+20%*H8) -> 457760 | J8: =+H8-I8 -> 831040 | K8: =IF(J8<=300000,7%*J8,IF(AND(J8>300000,J8<=600000),21000+(J8-300000)*11%,IF(AND(J8>600000,J8<=1100000),54000+(J8-600000)*15%,IF(AND(J8>1100000,J8<=1600000),129000+(J8-1100000)*19%,IF(AND(J8>1600000,J8<=3200000),224000+(J8-1600000)*21%,560000+(J8-3200000)*24%))))) -> 88656 | L8: =+K8/12 -> 7388 | N8: =100000/12 -> 8333.3333
A9: 5 | B9: JAMES | C9: QC | D9: 40000 | E9: =+D9*12 -> 480000 | F9: =8%*E9 -> 38400 | G9: =2.5%*E9 -> 12000 | H9: =+E9-F9-G9 -> 429600 | I9: =IF(1%*H9>200000,(1%*H9)+20%*H9,200000+20%*H9) -> 285920 | J9: =+H9-I9 -> 143680 | K9: =IF(J9<=300000,7%*J9,IF(AND(J9>300000,J9<=600000),21000+(J9-300000)*11%,IF(AND(J9>600000,J9<=1100000),54000+(J9-600000)*15%,IF(AND(J9>1100000,J9<=1600000),129000+(J9-1100000)*19%,IF(AND(J9>1600000,J9<=3200000),224000+(J9-1600000)*21%,560000+(J9-3200000)*24%))))) -> 10057.6 | L9: =+K9/12 -> 838.13333
A10: 6 | B10: CHUKA | C10: QC | D10: 150000 | E10: =+D10*12 -> 1800000 | F10: =8%*E10 -> 144000 | G10: =2.5%*E10 -> 45000 | H10: =+E10-F10-G10 -> 1611000 | I10: =IF(1%*H10>200000,(1%*H10)+20%*H10,200000+20%*H10) -> 522200 | J10: =+H10-I10 -> 1088800 | K10: =IF(J10<=300000,7%*J10,IF(AND(J10>300000,J10<=600000),21000+(J10-300000)*11%,IF(AND(J10>600000,J10<=1100000),54000+(J10-600000)*15%,IF(AND(J10>1100000,J10<=1600000),129000+(J10-1100000)*19%,IF(AND(J10>1600000,J10<=3200000),224000+(J10-1600000)*21%,560000+(J10-3200000)*24%))))) -> 127320 | L10: =+K10/12 -> 10610
A11: 7 | B11: ALICE | C11: HR | D11: 160000 | E11: =+D11*12 -> 1920000 | F11: =8%*E11 -> 153600 | G11: =2.5%*E11 -> 48000 | H11: =+E11-F11-G11 -> 1718400 | I11: =IF(1%*H11>200000,(1%*H11)+20%*H11,200000+20%*H11) -> 543680 | J11: =+H11-I11 -> 1174720 | K11: =IF(J11<=300000,7%*J11,IF(AND(J11>300000,J11<=600000),21000+(J11-300000)*11%,IF(AND(J11>600000,J11<=1100000),54000+(J11-600000)*15%,IF(AND(J11>1100000,J11<=1600000),129000+(J11-1100000)*19%,IF(AND(J11>1600000,J11<=3200000),224000+(J11-1600000)*21%,560000+(J11-3200000)*24%))))) -> 143196.8 | L11: =+K11/12 -> 11933.067
A12: 8 | B12: JOHN | C12: ACC | D12: 40000 | E12: =+D12*12 -> 480000 | F12: =8%*E12 -> 38400 | G12: =2.5%*E12 -> 12000 | H12: =+E12-F12-G12 -> 429600 | I12: =IF(1%*H12>200000,(1%*H12)+20%*H12,200000+20%*H12) -> 285920 | J12: =+H12-I12 -> 143680 | K12: =IF(J12<=300000,7%*J12,IF(AND(J12>300000,J12<=600000),21000+(J12-300000)*11%,IF(AND(J12>600000,J12<=1100000),54000+(J12-600000)*15%,IF(AND(J12>1100000,J12<=1600000),129000+(J12-1100000)*19%,IF(AND(J12>1600000,J12<=3200000),224000+(J12-1600000)*21%,560000+(J12-3200000)*24%))))) -> 10057.6 | L12: =+K12/12 -> 838.13333
A13: 9 | B13: ADAMU | C13: ACC | D13: 185000 | E13: =+D13*12 -> 2220000 | F13: =8%*E13 -> 177600 | G13: =2.5%*E13 -> 55500 | H13: =+E13-F13-G13 -> 1986900 | I13: =IF(1%*H13>200000,(1%*H13)+20%*H13,200000+20%*H13) -> 597380 | J13: =+H13-I13 -> 1389520 | K13: =IF(J13<=300000,7%*J13,IF(AND(J13>300000,J13<=600000),21000+(J13-300000)*11%,IF(AND(J13>600000,J13<=1100000),54000+(J13-600000)*15%,IF(AND(J13>1100000,J13<=1600000),129000+(J13-1100000)*19%,IF(AND(J13>1600000,J13<=3200000),224000+(J13-1600000)*21%,560000+(J13-3200000)*24%))))) -> 184008.8 | L13: =+K13/12 -> 15334.067
A14: 10 | B14: JIMOH | C14: AUD | D14: 250000 | E14: =+D14*12 -> 3000000 | F14: =8%*E14 -> 240000 | G14: =2.5%*E14 -> 75000 | H14: =+E14-F14-G14 -> 2685000 | I14: =IF(1%*H14>200000,(1%*H14)+20%*H14,200000+20%*H14) -> 737000 | J14: =+H14-I14 -> 1948000 | K14: =IF(J14<=300000,7%*J14,IF(AND(J14>300000,J14<=600000),21000+(J14-300000)*11%,IF(AND(J14>600000,J14<=1100000),54000+(J14-600000)*15%,IF(AND(J14>1100000,J14<=1600000),129000+(J14-1100000)*19%,IF(AND(J14>1600000,J14<=3200000),224000+(J14-1600000)*21%,560000+(J14-3200000)*24%))))) -> 297080 | L14: =+K14/12 -> 24756.667
A15: 11 | B15: IFEANYI | C15: SAFETY | D15: 50000 | E15: =+D15*12 -> 600000 | F15: =8%*E15 -> 48000 | G15: =2.5%*E15 -> 15000 | H15: =+E15-F15-G15 -> 537000 | I15: =IF(1%*H15>200000,(1%*H15)+20%*H15,200000+20%*H15) -> 307400 | J15: =+H15-I15 -> 229600 | K15: =IF(J15<=300000,7%*J15,IF(AND(J15>300000,J15<=600000),21000+(J15-300000)*11%,IF(AND(J15>600000,J15<=1100000),54000+(J15-600000)*15%,IF(AND(J15>1100000,J15<=1600000),129000+(J15-1100000)*19%,IF(AND(J15>1600000,J15<=3200000),224000+(J15-1600000)*21%,560000+(J15-3200000)*24%))))) -> 16072 | L15: =+K15/12 -> 1339.3333
A16: 12 | B16: BOSE | C16: WARE HS | D16: 47000 | E16: =+D16*12 -> 564000 | F16: =8%*E16 -> 45120 | G16: =2.5%*E16 -> 14100 | H16: =+E16-F16-G16 -> 504780 | I16: =IF(1%*H16>200000,(1%*H16)+20%*H16,200000+20%*H16) -> 300956 | J16: =+H16-I16 -> 203824 | K16: =IF(J16<=300000,7%*J16,IF(AND(J16>300000,J16<=600000),21000+(J16-300000)*11%,IF(AND(J16>600000,J16<=1100000),54000+(J16-600000)*15%,IF(AND(J16>1100000,J16<=1600000),129000+(J16-1100000)*19%,IF(AND(J16>1600000,J16<=3200000),224000+(J16-1600000)*21%,560000+(J16-3200000)*24%))))) -> 14267.68 | L16: =+K16/12 -> 1188.9733
A17: 13 | B17: HALIMA | C17: PRD | D17: 49000 | E17: =+D17*12 -> 588000 | F17: =8%*E17 -> 47040 | G17: =2.5%*E17 -> 14700 | H17: =+E17-F17-G17 -> 526260 | I17: =IF(1%*H17>200000,(1%*H17)+20%*H17,200000+20%*H17) -> 305252 | J17: =+H17-I17 -> 221008 | K17: =IF(J17<=300000,7%*J17,IF(AND(J17>300000,J17<=600000),21000+(J17-300000)*11%,IF(AND(J17>600000,J17<=1100000),54000+(J17-600000)*15%,IF(AND(J17>1100000,J17<=1600000),129000+(J17-1100000)*19%,IF(AND(J17>1600000,J17<=3200000),224000+(J17-1600000)*21%,560000+(J17-3200000)*24%))))) -> 15470.56 | L17: =+K17/12 -> 1289.2133
A18: 14 | B18: TOSIN | C18: PRD | D18: 52000 | E18: =+D18*12 -> 624000 | F18: =8%*E18 -> 49920 | G18: =2.5%*E18 -> 15600 | H18: =+E18-F18-G18 -> 558480 | I18: =IF(1%*H18>200000,(1%*H18)+20%*H18,200000+20%*H18) -> 311696 | J18: =+H18-I18 -> 246784 | K18: =IF(J18<=300000,7%*J18,IF(AND(J18>300000,J18<=600000),21000+(J18-300000)*11%,IF(AND(J18>600000,J18<=1100000),54000+(J18-600000)*15%,IF(AND(J18>1100000,J18<=1600000),129000+(J18-1100000)*19%,IF(AND(J18>1600000,J18<=3200000),224000+(J18-1600000)*21%,560000+(J18-3200000)*24%))))) -> 17274.88 | L18: =+K18/12 -> 1439.5733
A19: 15 | B19: AKANDE | C19: PRD | D19: 87000 | E19: =+D19*12 -> 1044000 | F19: =8%*E19 -> 83520 | G19: =2.5%*E19 -> 26100 | H19: =+E19-F19-G19 -> 934380 | I19: =IF(1%*H19>200000,(1%*H19)+20%*H19,200000+20%*H19) -> 386876 | J19: =+H19-I19 -> 547504 | K19: =IF(J19<=300000,7%*J19,IF(AND(J19>300000,J19<=600000),21000+(J19-300000)*11%,IF(AND(J19>600000,J19<=1100000),54000+(J19-600000)*15%,IF(AND(J19>1100000,J19<=1600000),129000+(J19-1100000)*19%,IF(AND(J19>1600000,J19<=3200000),224000+(J19-1600000)*21%,560000+(J19-3200000)*24%))))) -> 48225.44 | L19: =+K19/12 -> 4018.7867
A20: 16 | B20: WALE | C20: PRD | D20: 62140 | E20: =+D20*12 -> 745680 | F20: =8%*E20 -> 59654.4 | G20: =2.5%*E20 -> 18642 | H20: =+E20-F20-G20 -> 667383.6 | I20: =IF(1%*H20>200000,(1%*H20)+20%*H20,200000+20%*H20) -> 333476.72 | J20: =+H20-I20 -> 333906.88 | K20: =IF(J20<=300000,7%*J20,IF(AND(J20>300000,J20<=600000),21000+(J20-300000)*11%,IF(AND(J20>600000,J20<=1100000),54000+(J20-600000)*15%,IF(AND(J20>1100000,J20<=1600000),129000+(J20-1100000)*19%,IF(AND(J20>1600000,J20<=3200000),224000+(J20-1600000)*21%,560000+(J20-3200000)*24%))))) -> 24729.757 | L20: =+K20/12 -> 2060.8131
... A24: 20 | B24: FOLA | C24: PRD | D24: 88000 | E24: =+D24*12 -> 1056000 | F24: =8%*E24 -> 84480 | G24: =2.5%*E24 -> 26400 | H24: =+E24-F24-G24 -> 945120 | I24: =IF(1%*H24>200000,(1%*H24)+20%*H24,200000+20%*H24) -> 389024 | J24: =+H24-I24 -> 556096 | K24: =IF(J24<=300000,7%*J24,IF(AND(J24>300000,J24<=600000),21000+(J24-300000)*11%,IF(AND(J24>600000,J24<=1100000),54000+(J24-600000)*15%,IF(AND(J24>1100000,J24<=1600000),129000+(J24-1100000)*19%,IF(AND(J24>1600000,J24<=3200000),224000+(J24-1600000)*21%,560000+(J24-3200000)*24%))))) -> 49170.56 | L24: =+K24/12 -> 4097.5467
J1052: .

Sheet NEW PAYE
B2: Staff Details | G2: Gross Emolument Breakdown | M2: Statutory Deductions | R2: Chargeble Income | W2: TAX TABLE
E3: 12 | G3: 0.3 | H3: 0.3 | I3: 0.2 | J3: 0.1 | K3: 0.1 | M3: 0.08 | N3: 0.05 | O3: 0.025 | S3: 12 | W3: 0 | X3: 0.15 | Y3: 0.18 | Z3: 0.21 | AA3: 0.23 | AB3: 0.25 | AC3: Annual PAYE | AD3: Monthly PAYE | AE3: Monthly Net Pay | AF3: 0.1
W4: First | X4: Next | Y4: Next | Z4: Next | AA4: Next | AB4: Next | AF4: Employer's Contribution
B5: S/N | C5: Name | D5: Staff ID | E5: Annual Gross | F5: Monthly Gross Income | G5: BASIC | H5: HOUSING | I5: TRANSPORT | J5: UTILITY | K5: MEAL | L5: Gross Income 1 | M5: Employee Pension 8% of BHT | N5: NHIS 5% of basic salary | O5: NHF 2.5% of Gross Income | P5: Leave Allowance | Q5: Other Bonuses | R5: 13th Month/Bonus | S5: Gross Income 2 (Annual Income less statutory deductions) | T5: Annual Rent | U5: Rent Relief | V5: Chargeable Income | W5: 800000 | X5: 2200000 | Y5: 9000000 | Z5: 13000000 | AA5: 25000000 | AB5: 50000000 | AF5: Pension Contribution 10% (BHT)
B6: 1 | C6: SALIU AMINU | D6: OTL/0009 | E6: =$E$3*F6 -> 9000000 | F6: 750000 | G6: =F6*$G$3 -> 225000 | H6: =$H$3*F6 -> 225000 | I6: =$I$3*F6 -> 150000 | J6: =$J$3*F6 -> 75000 | K6: =$K$3*F6 -> 75000 | L6: =SUM(G6:K6) -> 750000 | M6: =$M$3*L6 -> 60000 | S6: =$S$3*(L6-M6-N6-O6) -> 8280000 | T6: 1500000 | U6: =IF(20%*T6>500000,500000,(20%*T6)) -> 300000 | V6: =S6-U6 -> 7980000 | W6: =IF($V6<$W$5,0,$W$5*$W$3) -> 0 | X6: =IF($V6-800000>=$X$5,$X$3*$X$5,IF($V6-800000<0,"-",$X$3*($V6-800000))) -> 330000 | Y6: =IF($V6-3000000>=$Y$5,$Y$3*$Y$5,IF($V6-3000000<0,"-",$Y$3*($V6-3000000))) -> 896400 | Z6: =IF($V6-12000000>=$Z$5,$Z$3*$Z$5,IF($V6-12000000<0,"-",$Z$3*($V6-12000000))) -> - | AA6: =IF($V6-25000000>=$AA$5,$AA$3*$AA$5,IF($V6-25000000<0,"-",$AA$3*($V6-25000000))) -> - | AB6: =IF($V6-25000000>0,$AB$3*($V6-25000000),"-") -> - | AC6: =SUM(W6:AB6) -> 1226400 | AD6: =AC6/12 -> 102200 | AE6: =L6-M6-N6-O6-AD6 -> 587800 | AF6: =(G6+H6+I6)*$AF$3 -> 60000
B7: 2 | C7: OLUDAYO BANKE | D7: OTL/0036 | E7: =$E$3*F7 -> 3600000 | F7: 300000 | G7: =F7*$G$3 -> 90000 | H7: =$H$3*F7 -> 90000 | I7: =$I$3*F7 -> 60000 | J7: =$J$3*F7 -> 30000 | K7: =$K$3*F7 -> 30000 | L7: =SUM(G7:K7) -> 300000 | M7: =$M$3*(G7+H7+I7) -> 19200 | S7: =$S$3*(L7-M7-N7-O7) -> 3369600 | T7: 120000 | U7: =IF(20%*T7>500000,500000,(20%*T7)) -> 24000 | V7: =S7-U7 -> 3345600 | W7: =IF($V7<$W$5,0,$W$5*$W$3) -> 0 | X7: =IF($V7-800000>=$X$5,$X$3*$X$5,IF($V7-800000<0,"-",$X$3*($V7-800000))) -> 330000 | Y7: =IF($V7-3000000>=$Y$5,$Y$3*$Y$5,IF($V7-3000000<0,"-",$Y$3*($V7-3000000))) -> 62208 | Z7: =IF($V7-12000000>=$Z$5,$Z$3*$Z$5,IF($V7-12000000<0,"-",$Z$3*($V7-12000000))) -> - | AA7: =IF($V7-25000000>=$AA$5,$AA$3*$AA$5,IF($V7-25000000<0,"-",$AA$3*($V7-25000000))) -> - | AB7: =IF($V7-25000000>0,$AB$3*($V7-25000000),"-") -> - | AC7: =SUM(W7:AB7) -> 392208 | AD7: =AC7/12 -> 32684 | AE7: =L7-M7-N7-O7-AD7 -> 248116 | AF7: =(G7+H7+I7)*$AF$3 -> 24000
